Workbook
Name SKINS: SUMMARY!$C$27

Sheet Master
B3: 3 | D3: Course | K3: Pure Michigan Open 2k21
H4: Front | T4: Back
E5: Hole | F5: 1 | G5: 2 | H5: 3 | I5: 4 | J5: 5 | K5: 6 | L5: 7 | M5: 8 | N5: 9 | O5: Out | Q5: 10 | R5: 11 | S5: 12 | T5: 13 | U5: 14 | V5: 15 | W5: 16 | X5: 17 | Y5: 18 | Z5: In | AA5: Total
E6: Color | O6: =SUM(F6:N6) -> 0 | Z6: =SUM(Q6:Y6) -> 0 | AA6: =Z6+O6 -> 0
E7: Par | O7: =SUM(F7:N7) -> 0 | Z7: =SUM(Q7:Y7) -> 0 | AA7: =Z7+O7 -> 0
E8: Handicap
E10: =IFERROR(VLOOKUP(D10,HANDICAPS!$B$8:$G$23,$B$3,FALSE),"") | F10: =IFERROR(IF($E10>18,IF(($E10-18)>F$33,"**","*"),IF($E10>=F$8,"*","")),"") -> * | G10: =IFERROR(IF($E10>18,IF(($E10-18)>G$33,"**","*"),IF($E10>=G$8,"*","")),"") -> * | H10: =IFERROR(IF($E10>18,IF(($E10-18)>H$33,"**","*"),IF($E10>=H$8,"*","")),"") -> * | I10: =IFERROR(IF($E10>18,IF(($E10-18)>I$33,"**","*"),IF($E10>=I$8,"*","")),"") -> * | J10: =IFERROR(IF($E10>18,IF(($E10-18)>J$33,"**","*"),IF($E10>=J$8,"*","")),"") -> * | K10: =IFERROR(IF($E10>18,IF(($E10-18)>K$33,"**","*"),IF($E10>=K$8,"*","")),"") -> * | L10: =IFERROR(IF($E10>18,IF(($E10-18)>L$33,"**","*"),IF($E10>=L$8,"*","")),"") -> * | M10: =IFERROR(IF($E10>18,IF(($E10-18)>M$33,"**","*"),IF($E10>=M$8,"*","")),"") -> * | N10: =IFERROR(IF($E10>18,IF(($E10-18)>N$33,"**","*"),IF($E10>=N$8,"*","")),"") -> * | O10: =IF(F11="","",SUM(F11:N11)) | Q10: =IFERROR(IF($E10>18,IF(($E10-18)>Q$33,"**","*"),IF($E10>=Q$8,"*","")),"") -> * | R10: =IFERROR(IF($E10>18,IF(($E10-18)>R$33,"**","*"),IF($E10>=R$8,"*","")),"") -> * | S10: =IFERROR(IF($E10>18,IF(($E10-18)>S$33,"**","*"),IF($E10>=S$8,"*","")),"") -> * | T10: =IFERROR(IF($E10>18,IF(($E10-18)>T$33,"**","*"),IF($E10>=T$8,"*","")),"") -> * | U10: =IFERROR(IF($E10>18,IF(($E10-18)>U$33,"**","*"),IF($E10>=U$8,"*","")),"") -> * | V10: =IFERROR(IF($E10>18,IF(($E10-18)>V$33,"**","*"),IF($E10>=V$8,"*","")),"") -> * | W10: =IFERROR(IF($E10>18,IF(($E10-18)>W$33,"**","*"),IF($E10>=W$8,"*","")),"") -> * | X10: =IFERROR(IF($E10>18,IF(($E10-18)>X$33,"**","*"),IF($E10>=X$8,"*","")),"") -> * | Y10: =IFERROR(IF($E10>18,IF(($E10-18)>Y$33,"**","*"),IF($E10>=Y$8,"*","")),"") -> * | Z10: =IF(Q11="","",SUM(Q11:Y11)) | AA10: =IF(Z10="","",SUM(O10,Z10))
E12: =IFERROR(VLOOKUP(D12,HANDICAPS!$B$8:$G$23,$B$3,FALSE),"") | F12: =IFERROR(IF($E12>18,IF(($E12-18)>F$33,"**","*"),IF($E12>=F$8,"*","")),"") -> * | G12: =IFERROR(IF($E12>18,IF(($E12-18)>G$33,"**","*"),IF($E12>=G$8,"*","")),"") -> * | H12: =IFERROR(IF($E12>18,IF(($E12-18)>H$33,"**","*"),IF($E12>=H$8,"*","")),"") -> * | I12: =IFERROR(IF($E12>18,IF(($E12-18)>I$33,"**","*"),IF($E12>=I$8,"*","")),"") -> * | J12: =IFERROR(IF($E12>18,IF(($E12-18)>J$33,"**","*"),IF($E12>=J$8,"*","")),"") -> * | K12: =IFERROR(IF($E12>18,IF(($E12-18)>K$33,"**","*"),IF($E12>=K$8,"*","")),"") -> * | L12: =IFERROR(IF($E12>18,IF(($E12-18)>L$33,"**","*"),IF($E12>=L$8,"*","")),"") -> * | M12: =IFERROR(IF($E12>18,IF(($E12-18)>M$33,"**","*"),IF($E12>=M$8,"*","")),"") -> * | N12: =IFERROR(IF($E12>18,IF(($E12-18)>N$33,"**","*"),IF($E12>=N$8,"*","")),"") -> * | O12: =IF(F13="","",SUM(F13:N13)) | Q12: =IFERROR(IF($E12>18,IF(($E12-18)>Q$33,"**","*"),IF($E12>=Q$8,"*","")),"") -> * | R12: =IFERROR(IF($E12>18,IF(($E12-18)>R$33,"**","*"),IF($E12>=R$8,"*","")),"") -> * | S12: =IFERROR(IF($E12>18,IF(($E12-18)>S$33,"**","*"),IF($E12>=S$8,"*","")),"") -> * | T12: =IFERROR(IF($E12>18,IF(($E12-18)>T$33,"**","*"),IF($E12>=T$8,"*","")),"") -> * | U12: =IFERROR(IF($E12>18,IF(($E12-18)>U$33,"**","*"),IF($E12>=U$8,"*","")),"") -> * | V12: =IFERROR(IF($E12>18,IF(($E12-18)>V$33,"**","*"),IF($E12>=V$8,"*","")),"") -> * | W12: =IFERROR(IF($E12>18,IF(($E12-18)>W$33,"**","*"),IF($E12>=W$8,"*","")),"") -> * | X12: =IFERROR(IF($E12>18,IF(($E12-18)>X$33,"**","*"),IF($E12>=X$8,"*","")),"") -> * | Y12: =IFERROR(IF($E12>18,IF(($E12-18)>Y$33,"**","*"),IF($E12>=Y$8,"*","")),"") -> * | Z12: =IF(Q13="","",SUM(Q13:Y13)) | AA12: =IF(Z12="","",SUM(O12,Z12))
D15: Best Ball (Net) | F15: =IF(F11="","",MIN(IF(F10="**",F11-2,IF(F10="*",F11-1,F11)),(IF(F12="**",F13-2,IF(F12="*",F13-1,F13))))) | G15: =IF(G11="","",MIN(IF(G10="**",G11-2,IF(G10="*",G11-1,G11)),(IF(G12="**",G13-2,IF(G12="*",G13-1,G13))))) | H15: =IF(H11="","",MIN(IF(H10="**",H11-2,IF(H10="*",H11-1,H11)),(IF(H12="**",H13-2,IF(H12="*",H13-1,H13))))) | I15: =IF(I11="","",MIN(IF(I10="**",I11-2,IF(I10="*",I11-1,I11)),(IF(I12="**",I13-2,IF(I12="*",I13-1,I13))))) | J15: =IF(J11="","",MIN(IF(J10="**",J11-2,IF(J10="*",J11-1,J11)),(IF(J12="**",J13-2,IF(J12="*",J13-1,J13))))) | K15: =IF(K11="","",MIN(IF(K10="**",K11-2,IF(K10="*",K11-1,K11)),(IF(K12="**",K13-2,IF(K12="*",K13-1,K13))))) | L15: =IF(L11="","",MIN(IF(L10="**",L11-2,IF(L10="*",L11-1,L11)),(IF(L12="**",L13-2,IF(L12="*",L13-1,L13))))) | M15: =IF(M11="","",MIN(IF(M10="**",M11-2,IF(M10="*",M11-1,M11)),(IF(M12="**",M13-2,IF(M12="*",M13-1,M13))))) | N15: =IF(N11="","",MIN(IF(N10="**",N11-2,IF(N10="*",N11-1,N11)),(IF(N12="**",N13-2,IF(N12="*",N13-1,N13))))) | O15: =IF(F15="","",SUM(F15:N15)) | Q15: =IF(Q11="","",MIN(IF(Q10="**",Q11-2,IF(Q10="*",Q11-1,Q11)),(IF(Q12="**",Q13-2,IF(Q12="*",Q13-1,Q13))))) | R15: =IF(R11="","",MIN(IF(R10="**",R11-2,IF(R10="*",R11-1,R11)),(IF(R12="**",R13-2,IF(R12="*",R13-1,R13))))) | S15: =IF(S11="","",MIN(IF(S10="**",S11-2,IF(S10="*",S11-1,S11)),(IF(S12="**",S13-2,IF(S12="*",S13-1,S13))))) | T15: =IF(T11="","",MIN(IF(T10="**",T11-2,IF(T10="*",T11-1,T11)),(IF(T12="**",T13-2,IF(T12="*",T13-1,T13))))) | U15: =IF(U11="","",MIN(IF(U10="**",U11-2,IF(U10="*",U11-1,U11)),(IF(U12="**",U13-2,IF(U12="*",U13-1,U13))))) | V15: =IF(V11="","",MIN(IF(V10="**",V11-2,IF(V10="*",V11-1,V11)),(IF(V12="**",V13-2,IF(V12="*",V13-1,V13))))) | W15: =IF(W11="","",MIN(IF(W10="**",W11-2,IF(W10="*",W11-1,W11)),(IF(W12="**",W13-2,IF(W12="*",W13-1,W13))))) | X15: =IF(X11="","",MIN(IF(X10="**",X11-2,IF(X10="*",X11-1,X11)),(IF(X12="**",X13-2,IF(X12="*",X13-1,X13))))) | Y15: =IF(Y11="","",MIN(IF(Y10="**",Y11-2,IF(Y10="*",Y11-1,Y11)),(IF(Y12="**",Y13-2,IF(Y12="*",Y13-1,Y13))))) | Z15: =IF(Q15="","",SUM(Q15:Y15)) | AA15: =IF(Z15="","",Z15+O15)
D16: Points | F16: =IF(F15="","",IF(F15=F23,0.5,IF(F15<F23,1,0))) | G16: =IF(G15="","",IF(G15=G23,0.5,IF(G15<G23,1,0))) | H16: =IF(H15="","",IF(H15=H23,0.5,IF(H15<H23,1,0))) | I16: =IF(I15="","",IF(I15=I23,0.5,IF(I15<I23,1,0))) | J16: =IF(J15="","",IF(J15=J23,0.5,IF(J15<J23,1,0))) | K16: =IF(K15="","",IF(K15=K23,0.5,IF(K15<K23,1,0))) | L16: =IF(L15="","",IF(L15=L23,0.5,IF(L15<L23,1,0))) | M16: =IF(M15="","",IF(M15=M23,0.5,IF(M15<M23,1,0))) | N16: =IF(N15="","",IF(N15=N23,0.5,IF(N15<N23,1,0))) | O16: =IF(F16="","",SUM(F16:N16)) | Q16: =IF(Q15="","",IF(Q15=Q23,0.5,IF(Q15<Q23,1,0))) | R16: =IF(R15="","",IF(R15=R23,0.5,IF(R15<R23,1,0))) | S16: =IF(S15="","",IF(S15=S23,0.5,IF(S15<S23,1,0))) | T16: =IF(T15="","",IF(T15=T23,0.5,IF(T15<T23,1,0))) | U16: =IF(U15="","",IF(U15=U23,0.5,IF(U15<U23,1,0))) | V16: =IF(V15="","",IF(V15=V23,0.5,IF(V15<V23,1,0))) | W16: =IF(W15="","",IF(W15=W23,0.5,IF(W15<W23,1,0))) | X16: =IF(X15="","",IF(X15=X23,0.5,IF(X15<X23,1,0))) | Y16: =IF(Y15="","",IF(Y15=Y23,0.5,IF(Y15<Y23,1,0))) | Z16: =IF(Q16="","",SUM(Q16:Y16)) | AA16: =IF(Z16="","",Z16+O16)
E18: =IFERROR(VLOOKUP(D18,HANDICAPS!$B$8:$G$23,$B$3,FALSE),"") | F18: =IFERROR(IF($E18>18,IF(($E18-18)>F$33,"**","*"),IF($E18>=F$8,"*","")),"") -> * | G18: =IFERROR(IF($E18>18,IF(($E18-18)>G$33,"**","*"),IF($E18>=G$8,"*","")),"") -> * | H18: =IFERROR(IF($E18>18,IF(($E18-18)>H$33,"**","*"),IF($E18>=H$8,"*","")),"") -> * | I18: =IFERROR(IF($E18>18,IF(($E18-18)>I$33,"**","*"),IF($E18>=I$8,"*","")),"") -> * | J18: =IFERROR(IF($E18>18,IF(($E18-18)>J$33,"**","*"),IF($E18>=J$8,"*","")),"") -> * | K18: =IFERROR(IF($E18>18,IF(($E18-18)>K$33,"**","*"),IF($E18>=K$8,"*","")),"") -> * | L18: =IFERROR(IF($E18>18,IF(($E18-18)>L$33,"**","*"),IF($E18>=L$8,"*","")),"") -> * | M18: =IFERROR(IF($E18>18,IF(($E18-18)>M$33,"**","*"),IF($E18>=M$8,"*","")),"") -> * | N18: =IFERROR(IF($E18>18,IF(($E18-18)>N$33,"**","*"),IF($E18>=N$8,"*","")),"") -> * | O18: =IF(F19="","",SUM(F19:N19)) | Q18: =IFERROR(IF($E18>18,IF(($E18-18)>Q$33,"**","*"),IF($E18>=Q$8,"*","")),"") -> * | R18: =IFERROR(IF($E18>18,IF(($E18-18)>R$33,"**","*"),IF($E18>=R$8,"*","")),"") -> * | S18: =IFERROR(IF($E18>18,IF(($E18-18)>S$33,"**","*"),IF($E18>=S$8,"*","")),"") -> * | T18: =IFERROR(IF($E18>18,IF(($E18-18)>T$33,"**","*"),IF($E18>=T$8,"*","")),"") -> * | U18: =IFERROR(IF($E18>18,IF(($E18-18)>U$33,"**","*"),IF($E18>=U$8,"*","")),"") -> * | V18: =IFERROR(IF($E18>18,IF(($E18-18)>V$33,"**","*"),IF($E18>=V$8,"*","")),"") -> * | W18: =IFERROR(IF($E18>18,IF(($E18-18)>W$33,"**","*"),IF($E18>=W$8,"*","")),"") -> * | X18: =IFERROR(IF($E18>18,IF(($E18-18)>X$33,"**","*"),IF($E18>=X$8,"*","")),"") -> * | Y18: =IFERROR(IF($E18>18,IF(($E18-18)>Y$33,"**","*"),IF($E18>=Y$8,"*","")),"") -> * | Z18: =IF(Q19="","",SUM(Q19:Y19)) | AA18: =IF(Z18="","",SUM(O18,Z18))
E20: =IFERROR(VLOOKUP(D20,HANDICAPS!$B$8:$G$23,$B$3,FALSE),"") | F20: =IFERROR(IF($E20>18,IF(($E20-18)>F$33,"**","*"),IF($E20>=F$8,"*","")),"") -> * | G20: =IFERROR(IF($E20>18,IF(($E20-18)>G$33,"**","*"),IF($E20>=G$8,"*","")),"") -> * | H20: =IFERROR(IF($E20>18,IF(($E20-18)>H$33,"**","*"),IF($E20>=H$8,"*","")),"") -> * | I20: =IFERROR(IF($E20>18,IF(($E20-18)>I$33,"**","*"),IF($E20>=I$8,"*","")),"") -> * | J20: =IFERROR(IF($E20>18,IF(($E20-18)>J$33,"**","*"),IF($E20>=J$8,"*","")),"") -> * | K20: =IFERROR(IF($E20>18,IF(($E20-18)>K$33,"**","*"),IF($E20>=K$8,"*","")),"") -> * | L20: =IFERROR(IF($E20>18,IF(($E20-18)>L$33,"**","*"),IF($E20>=L$8,"*","")),"") -> * | M20: =IFERROR(IF($E20>18,IF(($E20-18)>M$33,"**","*"),IF($E20>=M$8,"*","")),"") -> * | N20: =IFERROR(IF($E20>18,IF(($E20-18)>N$33,"**","*"),IF($E20>=N$8,"*","")),"") -> * | O20: =IF(F21="","",SUM(F21:N21)) | Q20: =IFERROR(IF($E20>18,IF(($E20-18)>Q$33,"**","*"),IF($E20>=Q$8,"*","")),"") -> * | R20: =IFERROR(IF($E20>18,IF(($E20-18)>R$33,"**","*"),IF($E20>=R$8,"*","")),"") -> * | S20: =IFERROR(IF($E20>18,IF(($E20-18)>S$33,"**","*"),IF($E20>=S$8,"*","")),"") -> * | T20: =IFERROR(IF($E20>18,IF(($E20-18)>T$33,"**","*"),IF($E20>=T$8,"*","")),"") -> * | U20: =IFERROR(IF($E20>18,IF(($E20-18)>U$33,"**","*"),IF($E20>=U$8,"*","")),"") -> * | V20: =IFERROR(IF($E20>18,IF(($E20-18)>V$33,"**","*"),IF($E20>=V$8,"*","")),"") -> * | W20: =IFERROR(IF($E20>18,IF(($E20-18)>W$33,"**","*"),IF($E20>=W$8,"*","")),"") -> * | X20: =IFERROR(IF($E20>18,IF(($E20-18)>X$33,"**","*"),IF($E20>=X$8,"*","")),"") -> * | Y20: =IFERROR(IF($E20>18,IF(($E20-18)>Y$33,"**","*"),IF($E20>=Y$8,"*","")),"") -> * | Z20: =IF(Q21="","",SUM(Q21:Y21)) | AA20: =IF(Z20="","",SUM(O20,Z20))
D23: Best Ball (Net) | F23: =IF(F19="","",MIN(IF(F18="**",F19-2,IF(F18="*",F19-1,F19)),(IF(F20="**",F21-2,IF(F20="*",F21-1,F21))))) | G23: =IF(G19="","",MIN(IF(G18="**",G19-2,IF(G18="*",G19-1,G19)),(IF(G20="**",G21-2,IF(G20="*",G21-1,G21))))) | H23: =IF(H19="","",MIN(IF(H18="**",H19-2,IF(H18="*",H19-1,H19)),(IF(H20="**",H21-2,IF(H20="*",H21-1,H21))))) | I23: =IF(I19="","",MIN(IF(I18="**",I19-2,IF(I18="*",I19-1,I19)),(IF(I20="**",I21-2,IF(I20="*",I21-1,I21))))) | J23: =IF(J19="","",MIN(IF(J18="**",J19-2,IF(J18="*",J19-1,J19)),(IF(J20="**",J21-2,IF(J20="*",J21-1,J21))))) | K23: =IF(K19="","",MIN(IF(K18="**",K19-2,IF(K18="*",K19-1,K19)),(IF(K20="**",K21-2,IF(K20="*",K21-1,K21))))) | L23: =IF(L19="","",MIN(IF(L18="**",L19-2,IF(L18="*",L19-1,L19)),(IF(L20="**",L21-2,IF(L20="*",L21-1,L21))))) | M23: =IF(M19="","",MIN(IF(M18="**",M19-2,IF(M18="*",M19-1,M19)),(IF(M20="**",M21-2,IF(M20="*",M21-1,M21))))) | N23: =IF(N19="","",MIN(IF(N18="**",N19-2,IF(N18="*",N19-1,N19)),(IF(N20="**",N21-2,IF(N20="*",N21-1,N21))))) | O23: =IF(F23="","",SUM(F23:N23)) | Q23: =IF(Q19="","",MIN(IF(Q18="**",Q19-2,IF(Q18="*",Q19-1,Q19)),(IF(Q20="**",Q21-2,IF(Q20="*",Q21-1,Q21))))) | R23: =IF(R19="","",MIN(IF(R18="**",R19-2,IF(R18="*",R19-1,R19)),(IF(R20="**",R21-2,IF(R20="*",R21-1,R21))))) | S23: =IF(S19="","",MIN(IF(S18="**",S19-2,IF(S18="*",S19-1,S19)),(IF(S20="**",S21-2,IF(S20="*",S21-1,S21))))) | T23: =IF(T19="","",MIN(IF(T18="**",T19-2,IF(T18="*",T19-1,T19)),(IF(T20="**",T21-2,IF(T20="*",T21-1,T21))))) | U23: =IF(U19="","",MIN(IF(U18="**",U19-2,IF(U18="*",U19-1,U19)),(IF(U20="**",U21-2,IF(U20="*",U21-1,U21))))) | V23: =IF(V19="","",MIN(IF(V18="**",V19-2,IF(V18="*",V19-1,V19)),(IF(V20="**",V21-2,IF(V20="*",V21-1,V21))))) | W23: =IF(W19="","",MIN(IF(W18="**",W19-2,IF(W18="*",W19-1,W19)),(IF(W20="**",W21-2,IF(W20="*",W21-1,W21))))) | X23: =IF(X19="","",MIN(IF(X18="**",X19-2,IF(X18="*",X19-1,X19)),(IF(X20="**",X21-2,IF(X20="*",X21-1,X21))))) | Y23: =IF(Y19="","",MIN(IF(Y18="**",Y19-2,IF(Y18="*",Y19-1,Y19)),(IF(Y20="**",Y21-2,IF(Y20="*",Y21-1,Y21))))) | Z23: =IF(Q23="","",SUM(Q23:Y23)) | AA23: =IF(Z23="","",Z23+O23)
D24: Points | F24: =IF(F23="","",IF(F23=F15,0.5,IF(F23<F15,1,0))) | G24: =IF(G23="","",IF(G23=G15,0.5,IF(G23<G15,1,0))) | H24: =IF(H23="","",IF(H23=H15,0.5,IF(H23<H15,1,0))) | I24: =IF(I23="","",IF(I23=I15,0.5,IF(I23<I15,1,0))) | J24: =IF(J23="","",IF(J23=J15,0.5,IF(J23<J15,1,0))) | K24: =IF(K23="","",IF(K23=K15,0.5,IF(K23<K15,1,0))) | L24: =IF(L23="","",IF(L23=L15,0.5,IF(L23<L15,1,0))) | M24: =IF(M23="","",IF(M23=M15,0.5,IF(M23<M15,1,0))) | N24: =IF(N23="","",IF(N23=N15,0.5,IF(N23<N15,1,0))) | O24: =IF(F24="","",SUM(F24:N24)) | Q24: =IF(Q23="","",IF(Q23=Q15,0.5,IF(Q23<Q15,1,0))) | R24: =IF(R23="","",IF(R23=R15,0.5,IF(R23<R15,1,0))) | S24: =IF(S23="","",IF(S23=S15,0.5,IF(S23<S15,1,0))) | T24: =IF(T23="","",IF(T23=T15,0.5,IF(T23<T15,1,0))) | U24: =IF(U23="","",IF(U23=U15,0.5,IF(U23<U15,1,0))) | V24: =IF(V23="","",IF(V23=V15,0.5,IF(V23<V15,1,0))) | W24: =IF(W23="","",IF(W23=W15,0.5,IF(W23<W15,1,0))) | X24: =IF(X23="","",IF(X23=X15,0.5,IF(X23<X15,1,0))) | Y24: =IF(Y23="","",IF(Y23=Y15,0.5,IF(Y23<Y15,1,0))) | Z24: =IF(Q24="","",SUM(Q24:Y24)) | AA24: =IF(Z24="","",Z24+O24)
D28: =D3 -> Course | K28: =K3 -> Pure Michigan Open 2k21
H29: =H4 -> Front | T29: =T4 -> Back
E30: Hole | F30: =F5 -> 1 | G30: =G5 -> 2 | H30: =H5 -> 3 | I30: =I5 -> 4 | J30: =J5 -> 5 | K30: =K5 -> 6 | L30: =L5 -> 7 | M30: =M5 -> 8 | ... O30: =O5 -> Out | Q30: =Q5 -> 10 | R30: =R5 -> 11 | S30: =S5 -> 12 | T30: =T5 -> 13 | U30: =U5 -> 14 | V30: =V5 -> 15 | W30: =W5 -> 16 | X30: =X5 -> 17 | ... Z30: =Z5 -> In | AA30: Total
E31: =E6 -> Color | F31: =F6 | G31: =G6 | H31: =H6 | I31: =I6 | J31: =J6 | K31: =K6 | L31: =L6 | ... O31: =O6 -> 0 | Q31: =Q6 | R31: =R6 | S31: =S6 | T31: =T6 | U31: =U6 | V31: =V6 | W31: =W6 | X31: =X6 | ... Z31: =Z6 -> 0 | AA31: =Z31+O31 -> 0
E32: Par | F32: =F7 | G32: =G7 | H32: =H7 | I32: =I7 | J32: =J7 | K32: =K7 | L32: =L7 | M32: =M7 | ... O32: =O7 -> 0 | Q32: =Q7 | R32: =R7 | S32: =S7 | T32: =T7 | U32: =U7 | V32: =V7 | W32: =W7 | X32: =X7 | ... Z32: =Z7 -> 0 | AA32: =Z32+O32 -> 0
E33: Handicap | F33: =F8 | G33: =G8 | H33: =H8 | I33: =I8 | J33: =J8 | K33: =K8 | L33: =L8 | M33: =M8 | N33: =N8 | Q33: =Q8 | R33: =R8 | S33: =S8 | T33: =T8 | U33: =U8 | V33: =V8 | W33: =W8 | X33: =X8 | Y33: =Y8
E35: =IFERROR(VLOOKUP(D35,HANDICAPS!$B$8:$G$23,$B$3,FALSE),"") | F35: =IFERROR(IF($E35>18,IF(($E35-18)>F$33,"**","*"),IF($E35>=F$8,"*","")),"") -> * | G35: =IFERROR(IF($E35>18,IF(($E35-18)>G$33,"**","*"),IF($E35>=G$8,"*","")),"") -> * | H35: =IFERROR(IF($E35>18,IF(($E35-18)>H$33,"**","*"),IF($E35>=H$8,"*","")),"") -> * | I35: =IFERROR(IF($E35>18,IF(($E35-18)>I$33,"**","*"),IF($E35>=I$8,"*","")),"") -> * | J35: =IFERROR(IF($E35>18,IF(($E35-18)>J$33,"**","*"),IF($E35>=J$8,"*","")),"") -> * | K35: =IFERROR(IF($E35>18,IF(($E35-18)>K$33,"**","*"),IF($E35>=K$8,"*","")),"") -> * | L35: =IFERROR(IF($E35>18,IF(($E35-18)>L$33,"**","*"),IF($E35>=L$8,"*","")),"") -> * | M35: =IFERROR(IF($E35>18,IF(($E35-18)>M$33,"**","*"),IF($E35>=M$8,"*","")),"") -> * | N35: =IFERROR(IF($E35>18,IF(($E35-18)>N$33,"**","*"),IF($E35>=N$8,"*","")),"") -> * | O35: =IF(F36="","",SUM(F36:N36)) | Q35: =IFERROR(IF($E35>18,IF(($E35-18)>Q$33,"**","*"),IF($E35>=Q$8,"*","")),"") -> * | R35: =IFERROR(IF($E35>18,IF(($E35-18)>R$33,"**","*"),IF($E35>=R$8,"*","")),"") -> * | S35: =IFERROR(IF($E35>18,IF(($E35-18)>S$33,"**","*"),IF($E35>=S$8,"*","")),"") -> * | T35: =IFERROR(IF($E35>18,IF(($E35-18)>T$33,"**","*"),IF($E35>=T$8,"*","")),"") -> * | U35: =IFERROR(IF($E35>18,IF(($E35-18)>U$33,"**","*"),IF($E35>=U$8,"*","")),"") -> * | V35: =IFERROR(IF($E35>18,IF(($E35-18)>V$33,"**","*"),IF($E35>=V$8,"*","")),"") -> * | W35: =IFERROR(IF($E35>18,IF(($E35-18)>W$33,"**","*"),IF($E35>=W$8,"*","")),"") -> * | X35: =IFERROR(IF($E35>18,IF(($E35-18)>X$33,"**","*"),IF($E35>=X$8,"*","")),"") -> * | Y35: =IFERROR(IF($E35>18,IF(($E35-18)>Y$33,"**","*"),IF($E35>=Y$8,"*","")),"") -> * | Z35: =IF(Q36="","",SUM(Q36:Y36)) | AA35: =IF(Z35="","",SUM(O35,Z35))
E37: =IFERROR(VLOOKUP(D37,HANDICAPS!$B$8:$G$23,$B$3,FALSE),"") | F37: =IFERROR(IF($E37>18,IF(($E37-18)>F$33,"**","*"),IF($E37>=F$8,"*","")),"") -> * | G37: =IFERROR(IF($E37>18,IF(($E37-18)>G$33,"**","*"),IF($E37>=G$8,"*","")),"") -> * | H37: =IFERROR(IF($E37>18,IF(($E37-18)>H$33,"**","*"),IF($E37>=H$8,"*","")),"") -> * | I37: =IFERROR(IF($E37>18,IF(($E37-18)>I$33,"**","*"),IF($E37>=I$8,"*","")),"") -> * | J37: =IFERROR(IF($E37>18,IF(($E37-18)>J$33,"**","*"),IF($E37>=J$8,"*","")),"") -> * | K37: =IFERROR(IF($E37>18,IF(($E37-18)>K$33,"**","*"),IF($E37>=K$8,"*","")),"") -> * | L37: =IFERROR(IF($E37>18,IF(($E37-18)>L$33,"**","*"),IF($E37>=L$8,"*","")),"") -> * | M37: =IFERROR(IF($E37>18,IF(($E37-18)>M$33,"**","*"),IF($E37>=M$8,"*","")),"") -> * | N37: =IFERROR(IF($E37>18,IF(($E37-18)>N$33,"**","*"),IF($E37>=N$8,"*","")),"") -> * | O37: =IF(F38="","",SUM(F38:N38)) | Q37: =IFERROR(IF($E37>18,IF(($E37-18)>Q$33,"**","*"),IF($E37>=Q$8,"*","")),"") -> * | R37: =IFERROR(IF($E37>18,IF(($E37-18)>R$33,"**","*"),IF($E37>=R$8,"*","")),"") -> * | S37: =IFERROR(IF($E37>18,IF(($E37-18)>S$33,"**","*"),IF($E37>=S$8,"*","")),"") -> * | T37: =IFERROR(IF($E37>18,IF(($E37-18)>T$33,"**","*"),IF($E37>=T$8,"*","")),"") -> * | U37: =IFERROR(IF($E37>18,IF(($E37-18)>U$33,"**","*"),IF($E37>=U$8,"*","")),"") -> * | V37: =IFERROR(IF($E37>18,IF(($E37-18)>V$33,"**","*"),IF($E37>=V$8,"*","")),"") -> * | W37: =IFERROR(IF($E37>18,IF(($E37-18)>W$33,"**","*"),IF($E37>=W$8,"*","")),"") -> * | X37: =IFERROR(IF($E37>18,IF(($E37-18)>X$33,"**","*"),IF($E37>=X$8,"*","")),"") -> * | Y37: =IFERROR(IF($E37>18,IF(($E37-18)>Y$33,"**","*"),IF($E37>=Y$8,"*","")),"") -> * | Z37: =IF(Q38="","",SUM(Q38:Y38)) | AA37: =IF(Z37="","",SUM(O37,Z37))
D40: Best Ball (Net) | F40: =IF(F36="","",MIN(IF(F35="**",F36-2,IF(F35="*",F36-1,F36)),(IF(F37="**",F38-2,IF(F37="*",F38-1,F38))))) | G40: =IF(G36="","",MIN(IF(G35="**",G36-2,IF(G35="*",G36-1,G36)),(IF(G37="**",G38-2,IF(G37="*",G38-1,G38))))) | H40: =IF(H36="","",MIN(IF(H35="**",H36-2,IF(H35="*",H36-1,H36)),(IF(H37="**",H38-2,IF(H37="*",H38-1,H38))))) | I40: =IF(I36="","",MIN(IF(I35="**",I36-2,IF(I35="*",I36-1,I36)),(IF(I37="**",I38-2,IF(I37="*",I38-1,I38))))) | J40: =IF(J36="","",MIN(IF(J35="**",J36-2,IF(J35="*",J36-1,J36)),(IF(J37="**",J38-2,IF(J37="*",J38-1,J38))))) | K40: =IF(K36="","",MIN(IF(K35="**",K36-2,IF(K35="*",K36-1,K36)),(IF(K37="**",K38-2,IF(K37="*",K38-1,K38))))) | L40: =IF(L36="","",MIN(IF(L35="**",L36-2,IF(L35="*",L36-1,L36)),(IF(L37="**",L38-2,IF(L37="*",L38-1,L38))))) | M40: =IF(M36="","",MIN(IF(M35="**",M36-2,IF(M35="*",M36-1,M36)),(IF(M37="**",M38-2,IF(M37="*",M38-1,M38))))) | N40: =IF(N36="","",MIN(IF(N35="**",N36-2,IF(N35="*",N36-1,N36)),(IF(N37="**",N38-2,IF(N37="*",N38-1,N38))))) | O40: =IF(F40="","",SUM(F40:N40)) | Q40: =IF(Q36="","",MIN(IF(Q35="**",Q36-2,IF(Q35="*",Q36-1,Q36)),(IF(Q37="**",Q38-2,IF(Q37="*",Q38-1,Q38))))) | R40: =IF(R36="","",MIN(IF(R35="**",R36-2,IF(R35="*",R36-1,R36)),(IF(R37="**",R38-2,IF(R37="*",R38-1,R38))))) | S40: =IF(S36="","",MIN(IF(S35="**",S36-2,IF(S35="*",S36-1,S36)),(IF(S37="**",S38-2,IF(S37="*",S38-1,S38))))) | T40: =IF(T36="","",MIN(IF(T35="**",T36-2,IF(T35="*",T36-1,T36)),(IF(T37="**",T38-2,IF(T37="*",T38-1,T38))))) | U40: =IF(U36="","",MIN(IF(U35="**",U36-2,IF(U35="*",U36-1,U36)),(IF(U37="**",U38-2,IF(U37="*",U38-1,U38))))) | V40: =IF(V36="","",MIN(IF(V35="**",V36-2,IF(V35="*",V36-1,V36)),(IF(V37="**",V38-2,IF(V37="*",V38-1,V38))))) | W40: =IF(W36="","",MIN(IF(W35="**",W36-2,IF(W35="*",W36-1,W36)),(IF(W37="**",W38-2,IF(W37="*",W38-1,W38))))) | X40: =IF(X36="","",MIN(IF(X35="**",X36-2,IF(X35="*",X36-1,X36)),(IF(X37="**",X38-2,IF(X37="*",X38-1,X38))))) | Y40: =IF(Y36="","",MIN(IF(Y35="**",Y36-2,IF(Y35="*",Y36-1,Y36)),(IF(Y37="**",Y38-2,IF(Y37="*",Y38-1,Y38))))) | Z40: =IF(Q40="","",SUM(Q40:Y40)) | AA40: =IF(Z40="","",Z40+O40)
D41: Points | F41: =IF(F40="","",IF(F40=F48,0.5,IF(F40<F48,1,0))) | G41: =IF(G40="","",IF(G40=G48,0.5,IF(G40<G48,1,0))) | H41: =IF(H40="","",IF(H40=H48,0.5,IF(H40<H48,1,0))) | I41: =IF(I40="","",IF(I40=I48,0.5,IF(I40<I48,1,0))) | J41: =IF(J40="","",IF(J40=J48,0.5,IF(J40<J48,1,0))) | K41: =IF(K40="","",IF(K40=K48,0.5,IF(K40<K48,1,0))) | L41: =IF(L40="","",IF(L40=L48,0.5,IF(L40<L48,1,0))) | M41: =IF(M40="","",IF(M40=M48,0.5,IF(M40<M48,1,0))) | N41: =IF(N40="","",IF(N40=N48,0.5,IF(N40<N48,1,0))) | O41: =IF(F41="","",SUM(F41:N41)) | Q41: =IF(Q40="","",IF(Q40=Q48,0.5,IF(Q40<Q48,1,0))) | R41: =IF(R40="","",IF(R40=R48,0.5,IF(R40<R48,1,0))) | S41: =IF(S40="","",IF(S40=S48,0.5,IF(S40<S48,1,0))) | T41: =IF(T40="","",IF(T40=T48,0.5,IF(T40<T48,1,0))) | U41: =IF(U40="","",IF(U40=U48,0.5,IF(U40<U48,1,0))) | V41: =IF(V40="","",IF(V40=V48,0.5,IF(V40<V48,1,0))) | W41: =IF(W40="","",IF(W40=W48,0.5,IF(W40<W48,1,0))) | X41: =IF(X40="","",IF(X40=X48,0.5,IF(X40<X48,1,0))) | Y41: =IF(Y40="","",IF(Y40=Y48,0.5,IF(Y40<Y48,1,0))) | Z41: =IF(Q41="","",SUM(Q41:Y41)) | AA41: =IF(Z41="","",Z41+O41)
E43: =IFERROR(VLOOKUP(D43,HANDICAPS!$B$8:$G$23,$B$3,FALSE),"") | F43: =IFERROR(IF($E43>18,IF(($E43-18)>F$33,"**","*"),IF($E43>=F$8,"*","")),"") -> * | G43: =IFERROR(IF($E43>18,IF(($E43-18)>G$33,"**","*"),IF($E43>=G$8,"*","")),"") -> * | H43: =IFERROR(IF($E43>18,IF(($E43-18)>H$33,"**","*"),IF($E43>=H$8,"*","")),"") -> * | I43: =IFERROR(IF($E43>18,IF(($E43-18)>I$33,"**","*"),IF($E43>=I$8,"*","")),"") -> * | J43: =IFERROR(IF($E43>18,IF(($E43-18)>J$33,"**","*"),IF($E43>=J$8,"*","")),"") -> * | K43: =IFERROR(IF($E43>18,IF(($E43-18)>K$33,"**","*"),IF($E43>=K$8,"*","")),"") -> * | L43: =IFERROR(IF($E43>18,IF(($E43-18)>L$33,"**","*"),IF($E43>=L$8,"*","")),"") -> * | M43: =IFERROR(IF($E43>18,IF(($E43-18)>M$33,"**","*"),IF($E43>=M$8,"*","")),"") -> * | N43: =IFERROR(IF($E43>18,IF(($E43-18)>N$33,"**","*"),IF($E43>=N$8,"*","")),"") -> * | O43: =IF(F44="","",SUM(F44:N44)) | Q43: =IFERROR(IF($E43>18,IF(($E43-18)>Q$33,"**","*"),IF($E43>=Q$8,"*","")),"") -> * | R43: =IFERROR(IF($E43>18,IF(($E43-18)>R$33,"**","*"),IF($E43>=R$8,"*","")),"") -> * | S43: =IFERROR(IF($E43>18,IF(($E43-18)>S$33,"**","*"),IF($E43>=S$8,"*","")),"") -> * | T43: =IFERROR(IF($E43>18,IF(($E43-18)>T$33,"**","*"),IF($E43>=T$8,"*","")),"") -> * | U43: =IFERROR(IF($E43>18,IF(($E43-18)>U$33,"**","*"),IF($E43>=U$8,"*","")),"") -> * | V43: =IFERROR(IF($E43>18,IF(($E43-18)>V$33,"**","*"),IF($E43>=V$8,"*","")),"") -> * | W43: =IFERROR(IF($E43>18,IF(($E43-18)>W$33,"**","*"),IF($E43>=W$8,"*","")),"") -> * | X43: =IFERROR(IF($E43>18,IF(($E43-18)>X$33,"**","*"),IF($E43>=X$8,"*","")),"") -> * | Y43: =IFERROR(IF($E43>18,IF(($E43-18)>Y$33,"**","*"),IF($E43>=Y$8,"*","")),"") -> * | Z43: =IF(Q44="","",SUM(Q44:Y44)) | AA43: =IF(Z43="","",SUM(O43,Z43))
E45: =IFERROR(VLOOKUP(D45,HANDICAPS!$B$8:$G$23,$B$3,FALSE),"") | F45: =IFERROR(IF($E45>18,IF(($E45-18)>F$33,"**","*"),IF($E45>=F$8,"*","")),"") -> * | G45: =IFERROR(IF($E45>18,IF(($E45-18)>G$33,"**","*"),IF($E45>=G$8,"*","")),"") -> * | H45: =IFERROR(IF($E45>18,IF(($E45-18)>H$33,"**","*"),IF($E45>=H$8,"*","")),"") -> * | I45: =IFERROR(IF($E45>18,IF(($E45-18)>I$33,"**","*"),IF($E45>=I$8,"*","")),"") -> * | J45: =IFERROR(IF($E45>18,IF(($E45-18)>J$33,"**","*"),IF($E45>=J$8,"*","")),"") -> * | K45: =IFERROR(IF($E45>18,IF(($E45-18)>K$33,"**","*"),IF($E45>=K$8,"*","")),"") -> * | L45: =IFERROR(IF($E45>18,IF(($E45-18)>L$33,"**","*"),IF($E45>=L$8,"*","")),"") -> * | M45: =IFERROR(IF($E45>18,IF(($E45-18)>M$33,"**","*"),IF($E45>=M$8,"*","")),"") -> * | N45: =IFERROR(IF($E45>18,IF(($E45-18)>N$33,"**","*"),IF($E45>=N$8,"*","")),"") -> * | O45: =IF(F46="","",SUM(F46:N46)) | Q45: =IFERROR(IF($E45>18,IF(($E45-18)>Q$33,"**","*"),IF($E45>=Q$8,"*","")),"") -> * | R45: =IFERROR(IF($E45>18,IF(($E45-18)>R$33,"**","*"),IF($E45>=R$8,"*","")),"") -> * | S45: =IFERROR(IF($E45>18,IF(($E45-18)>S$33,"**","*"),IF($E45>=S$8,"*","")),"") -> * | T45: =IFERROR(IF($E45>18,IF(($E45-18)>T$33,"**","*"),IF($E45>=T$8,"*","")),"") -> * | U45: =IFERROR(IF($E45>18,IF(($E45-18)>U$33,"**","*"),IF($E45>=U$8,"*","")),"") -> * | V45: =IFERROR(IF($E45>18,IF(($E45-18)>V$33,"**","*"),IF($E45>=V$8,"*","")),"") -> * | W45: =IFERROR(IF($E45>18,IF(($E45-18)>W$33,"**","*"),IF($E45>=W$8,"*","")),"") -> * | X45: =IFERROR(IF($E45>18,IF(($E45-18)>X$33,"**","*"),IF($E45>=X$8,"*","")),"") -> * | Y45: =IFERROR(IF($E45>18,IF(($E45-18)>Y$33,"**","*"),IF($E45>=Y$8,"*","")),"") -> * | Z45: =IF(Q46="","",SUM(Q46:Y46)) | AA45: =IF(Z45="","",SUM(O45,Z45))
D48: Best Ball (Net) | F48: =IF(F44="","",MIN(IF(F43="**",F44-2,IF(F43="*",F44-1,F44)),(IF(F45="**",F46-2,IF(F45="*",F46-1,F46))))) | G48: =IF(G44="","",MIN(IF(G43="**",G44-2,IF(G43="*",G44-1,G44)),(IF(G45="**",G46-2,IF(G45="*",G46-1,G46))))) | H48: =IF(H44="","",MIN(IF(H43="**",H44-2,IF(H43="*",H44-1,H44)),(IF(H45="**",H46-2,IF(H45="*",H46-1,H46))))) | I48: =IF(I44="","",MIN(IF(I43="**",I44-2,IF(I43="*",I44-1,I44)),(IF(I45="**",I46-2,IF(I45="*",I46-1,I46))))) | J48: =IF(J44="","",MIN(IF(J43="**",J44-2,IF(J43="*",J44-1,J44)),(IF(J45="**",J46-2,IF(J45="*",J46-1,J46))))) | K48: =IF(K44="","",MIN(IF(K43="**",K44-2,IF(K43="*",K44-1,K44)),(IF(K45="**",K46-2,IF(K45="*",K46-1,K46))))) | L48: =IF(L44="","",MIN(IF(L43="**",L44-2,IF(L43="*",L44-1,L44)),(IF(L45="**",L46-2,IF(L45="*",L46-1,L46))))) | M48: =IF(M44="","",MIN(IF(M43="**",M44-2,IF(M43="*",M44-1,M44)),(IF(M45="**",M46-2,IF(M45="*",M46-1,M46))))) | N48: =IF(N44="","",MIN(IF(N43="**",N44-2,IF(N43="*",N44-1,N44)),(IF(N45="**",N46-2,IF(N45="*",N46-1,N46))))) | O48: =IF(F48="","",SUM(F48:N48)) | Q48: =IF(Q44="","",MIN(IF(Q43="**",Q44-2,IF(Q43="*",Q44-1,Q44)),(IF(Q45="**",Q46-2,IF(Q45="*",Q46-1,Q46))))) | R48: =IF(R44="","",MIN(IF(R43="**",R44-2,IF(R43="*",R44-1,R44)),(IF(R45="**",R46-2,IF(R45="*",R46-1,R46))))) | S48: =IF(S44="","",MIN(IF(S43="**",S44-2,IF(S43="*",S44-1,S44)),(IF(S45="**",S46-2,IF(S45="*",S46-1,S46))))) | T48: =IF(T44="","",MIN(IF(T43="**",T44-2,IF(T43="*",T44-1,T44)),(IF(T45="**",T46-2,IF(T45="*",T46-1,T46))))) | U48: =IF(U44="","",MIN(IF(U43="**",U44-2,IF(U43="*",U44-1,U44)),(IF(U45="**",U46-2,IF(U45="*",U46-1,U46))))) | V48: =IF(V44="","",MIN(IF(V43="**",V44-2,IF(V43="*",V44-1,V44)),(IF(V45="**",V46-2,IF(V45="*",V46-1,V46))))) | W48: =IF(W44="","",MIN(IF(W43="**",W44-2,IF(W43="*",W44-1,W44)),(IF(W45="**",W46-2,IF(W45="*",W46-1,W46))))) | X48: =IF(X44="","",MIN(IF(X43="**",X44-2,IF(X43="*",X44-1,X44)),(IF(X45="**",X46-2,IF(X45="*",X46-1,X46))))) | Y48: =IF(Y44="","",MIN(IF(Y43="**",Y44-2,IF(Y43="*",Y44-1,Y44)),(IF(Y45="**",Y46-2,IF(Y45="*",Y46-1,Y46))))) | Z48: =IF(Q48="","",SUM(Q48:Y48)) | AA48: =IF(Z48="","",Z48+O48)
D49: Points | F49: =IF(F48="","",IF(F48=F40,0.5,IF(F48<F40,1,0))) | G49: =IF(G48="","",IF(G48=G40,0.5,IF(G48<G40,1,0))) | H49: =IF(H48="","",IF(H48=H40,0.5,IF(H48<H40,1,0))) | I49: =IF(I48="","",IF(I48=I40,0.5,IF(I48<I40,1,0))) | J49: =IF(J48="","",IF(J48=J40,0.5,IF(J48<J40,1,0))) | K49: =IF(K48="","",IF(K48=K40,0.5,IF(K48<K40,1,0))) | L49: =IF(L48="","",IF(L48=L40,0.5,IF(L48<L40,1,0))) | M49: =IF(M48="","",IF(M48=M40,0.5,IF(M48<M40,1,0))) | N49: =IF(N48="","",IF(N48=N40,0.5,IF(N48<N40,1,0))) | O49: =IF(F49="","",SUM(F49:N49)) | Q49: =IF(Q48="","",IF(Q48=Q40,0.5,IF(Q48<Q40,1,0))) | R49: =IF(R48="","",IF(R48=R40,0.5,IF(R48<R40,1,0))) | S49: =IF(S48="","",IF(S48=S40,0.5,IF(S48<S40,1,0))) | T49: =IF(T48="","",IF(T48=T40,0.5,IF(T48<T40,1,0))) | U49: =IF(U48="","",IF(U48=U40,0.5,IF(U48<U40,1,0))) | V49: =IF(V48="","",IF(V48=V40,0.5,IF(V48<V40,1,0))) | W49: =IF(W48="","",IF(W48=W40,0.5,IF(W48<W40,1,0))) | X49: =IF(X48="","",IF(X48=X40,0.5,IF(X48<X40,1,0))) | Y49: =IF(Y48="","",IF(Y48=Y40,0.5,IF(Y48<Y40,1,0))) | Z49: =IF(Q49="","",SUM(Q49:Y49)) | AA49: =IF(Z49="","",Z49+O49)
D53: =D28 -> Course | K53: =K28 -> Pure Michigan Open 2k21
H54: =H29 -> Front | T54: =T29 -> Back
E55: Hole | F55: =F30 -> 1 | G55: =G30 -> 2 | H55: =H30 -> 3 | I55: =I30 -> 4 | J55: =J30 -> 5 | K55: =K30 -> 6 | L55: =L30 -> 7 | M55: =M30 -> 8 | ... O55: =O30 -> Out | Q55: =Q30 -> 10 | R55: =R30 -> 11 | S55: =S30 -> 12 | T55: =T30 -> 13 | U55: =U30 -> 14 | V55: =V30 -> 15 | W55: =W30 -> 16 | X55: =X30 -> 17 | ... Z55: =Z30 -> In | AA55: Total
E56: =E31 -> Color | F56: =F31 | G56: =G31 | H56: =H31 | I56: =I31 | J56: =J31 | K56: =K31 | L56: =L31 | ... O56: =O31 -> 0 | Q56: =Q31 | R56: =R31 | S56: =S31 | T56: =T31 | U56: =U31 | V56: =V31 | W56: =W31 | X56: =X31 | ... Z56: =Z31 -> 0 | AA56: =Z56+O56 -> 0
E57: Par | F57: =F32 | G57: =G32 | H57: =H32 | I57: =I32 | J57: =J32 | K57: =K32 | L57: =L32 | M57: =M32 | ... O57: =O32 -> 0 | Q57: =Q32 | R57: =R32 | S57: =S32 | T57: =T32 | U57: =U32 | V57: =V32 | W57: =W32 | X57: =X32 | ... Z57: =Z32 -> 0 | AA57: =Z57+O57 -> 0
E58: Handicap | F58: =F33 | G58: =G33 | H58: =H33 | I58: =I33 | J58: =J33 | K58: =K33 | L58: =L33 | M58: =M33 | N58: =N33 | Q58: =Q33 | R58: =R33 | S58: =S33 | T58: =T33 | U58: =U33 | V58: =V33 | W58: =W33 | X58: =X33 | Y58: =Y33
E60: =IFERROR(VLOOKUP(D60,HANDICAPS!$B$8:$G$23,$B$3,FALSE),"") | F60: =IFERROR(IF($E60>18,IF(($E60-18)>F$33,"**","*"),IF($E60>=F$8,"*","")),"") -> * | G60: =IFERROR(IF($E60>18,IF(($E60-18)>G$33,"**","*"),IF($E60>=G$8,"*","")),"") -> * | H60: =IFERROR(IF($E60>18,IF(($E60-18)>H$33,"**","*"),IF($E60>=H$8,"*","")),"") -> * | I60: =IFERROR(IF($E60>18,IF(($E60-18)>I$33,"**","*"),IF($E60>=I$8,"*","")),"") -> * | J60: =IFERROR(IF($E60>18,IF(($E60-18)>J$33,"**","*"),IF($E60>=J$8,"*","")),"") -> * | K60: =IFERROR(IF($E60>18,IF(($E60-18)>K$33,"**","*"),IF($E60>=K$8,"*","")),"") -> * | L60: =IFERROR(IF($E60>18,IF(($E60-18)>L$33,"**","*"),IF($E60>=L$8,"*","")),"") -> * | M60: =IFERROR(IF($E60>18,IF(($E60-18)>M$33,"**","*"),IF($E60>=M$8,"*","")),"") -> * | N60: =IFERROR(IF($E60>18,IF(($E60-18)>N$33,"**","*"),IF($E60>=N$8,"*","")),"") -> * | O60: =IF(F61="","",SUM(F61:N61)) | Q60: =IFERROR(IF($E60>18,IF(($E60-18)>Q$33,"**","*"),IF($E60>=Q$8,"*","")),"") -> * | R60: =IFERROR(IF($E60>18,IF(($E60-18)>R$33,"**","*"),IF($E60>=R$8,"*","")),"") -> * | S60: =IFERROR(IF($E60>18,IF(($E60-18)>S$33,"**","*"),IF($E60>=S$8,"*","")),"") -> * | T60: =IFERROR(IF($E60>18,IF(($E60-18)>T$33,"**","*"),IF($E60>=T$8,"*","")),"") -> * | U60: =IFERROR(IF($E60>18,IF(($E60-18)>U$33,"**","*"),IF($E60>=U$8,"*","")),"") -> * | V60: =IFERROR(IF($E60>18,IF(($E60-18)>V$33,"**","*"),IF($E60>=V$8,"*","")),"") -> * | W60: =IFERROR(IF($E60>18,IF(($E60-18)>W$33,"**","*"),IF($E60>=W$8,"*","")),"") -> * | X60: =IFERROR(IF($E60>18,IF(($E60-18)>X$33,"**","*"),IF($E60>=X$8,"*","")),"") -> * | Y60: =IFERROR(IF($E60>18,IF(($E60-18)>Y$33,"**","*"),IF($E60>=Y$8,"*","")),"") -> * | Z60: =IF(Q61="","",SUM(Q61:Y61)) | AA60: =IF(Z60="","",SUM(O60,Z60))
E62: =IFERROR(VLOOKUP(D62,HANDICAPS!$B$8:$G$23,$B$3,FALSE),"") | F62: =IFERROR(IF($E62>18,IF(($E62-18)>F$33,"**","*"),IF($E62>=F$8,"*","")),"") -> * | G62: =IFERROR(IF($E62>18,IF(($E62-18)>G$33,"**","*"),IF($E62>=G$8,"*","")),"") -> * | H62: =IFERROR(IF($E62>18,IF(($E62-18)>H$33,"**","*"),IF($E62>=H$8,"*","")),"") -> * | I62: =IFERROR(IF($E62>18,IF(($E62-18)>I$33,"**","*"),IF($E62>=I$8,"*","")),"") -> * | J62: =IFERROR(IF($E62>18,IF(($E62-18)>J$33,"**","*"),IF($E62>=J$8,"*","")),"") -> * | K62: =IFERROR(IF($E62>18,IF(($E62-18)>K$33,"**","*"),IF($E62>=K$8,"*","")),"") -> * | L62: =IFERROR(IF($E62>18,IF(($E62-18)>L$33,"**","*"),IF($E62>=L$8,"*","")),"") -> * | M62: =IFERROR(IF($E62>18,IF(($E62-18)>M$33,"**","*"),IF($E62>=M$8,"*","")),"") -> * | N62: =IFERROR(IF($E62>18,IF(($E62-18)>N$33,"**","*"),IF($E62>=N$8,"*","")),"") -> * | O62: =IF(F63="","",SUM(F63:N63)) | Q62: =IFERROR(IF($E62>18,IF(($E62-18)>Q$33,"**","*"),IF($E62>=Q$8,"*","")),"") -> * | R62: =IFERROR(IF($E62>18,IF(($E62-18)>R$33,"**","*"),IF($E62>=R$8,"*","")),"") -> * | S62: =IFERROR(IF($E62>18,IF(($E62-18)>S$33,"**","*"),IF($E62>=S$8,"*","")),"") -> * | T62: =IFERROR(IF($E62>18,IF(($E62-18)>T$33,"**","*"),IF($E62>=T$8,"*","")),"") -> * | U62: =IFERROR(IF($E62>18,IF(($E62-18)>U$33,"**","*"),IF($E62>=U$8,"*","")),"") -> * | V62: =IFERROR(IF($E62>18,IF(($E62-18)>V$33,"**","*"),IF($E62>=V$8,"*","")),"") -> * | W62: =IFERROR(IF($E62>18,IF(($E62-18)>W$33,"**","*"),IF($E62>=W$8,"*","")),"") -> * | X62: =IFERROR(IF($E62>18,IF(($E62-18)>X$33,"**","*"),IF($E62>=X$8,"*","")),"") -> * | Y62: =IFERROR(IF($E62>18,IF(($E62-18)>Y$33,"**","*"),IF($E62>=Y$8,"*","")),"") -> * | Z62: =IF(Q63="","",SUM(Q63:Y63)) | AA62: =IF(Z62="","",SUM(O62,Z62))
D65: Best Ball (Net) | F65: =IF(F61="","",MIN(IF(F60="**",F61-2,IF(F60="*",F61-1,F61)),(IF(F62="**",F63-2,IF(F62="*",F63-1,F63))))) | G65: =IF(G61="","",MIN(IF(G60="**",G61-2,IF(G60="*",G61-1,G61)),(IF(G62="**",G63-2,IF(G62="*",G63-1,G63))))) | H65: =IF(H61="","",MIN(IF(H60="**",H61-2,IF(H60="*",H61-1,H61)),(IF(H62="**",H63-2,IF(H62="*",H63-1,H63))))) | I65: =IF(I61="","",MIN(IF(I60="**",I61-2,IF(I60="*",I61-1,I61)),(IF(I62="**",I63-2,IF(I62="*",I63-1,I63))))) | J65: =IF(J61="","",MIN(IF(J60="**",J61-2,IF(J60="*",J61-1,J61)),(IF(J62="**",J63-2,IF(J62="*",J63-1,J63))))) | K65: =IF(K61="","",MIN(IF(K60="**",K61-2,IF(K60="*",K61-1,K61)),(IF(K62="**",K63-2,IF(K62="*",K63-1,K63))))) | L65: =IF(L61="","",MIN(IF(L60="**",L61-2,IF(L60="*",L61-1,L61)),(IF(L62="**",L63-2,IF(L62="*",L63-1,L63))))) | M65: =IF(M61="","",MIN(IF(M60="**",M61-2,IF(M60="*",M61-1,M61)),(IF(M62="**",M63-2,IF(M62="*",M63-1,M63))))) | N65: =IF(N61="","",MIN(IF(N60="**",N61-2,IF(N60="*",N61-1,N61)),(IF(N62="**",N63-2,IF(N62="*",N63-1,N63))))) | O65: =IF(F65="","",SUM(F65:N65)) | Q65: =IF(Q61="","",MIN(IF(Q60="**",Q61-2,IF(Q60="*",Q61-1,Q61)),(IF(Q62="**",Q63-2,IF(Q62="*",Q63-1,Q63))))) | R65: =IF(R61="","",MIN(IF(R60="**",R61-2,IF(R60="*",R61-1,R61)),(IF(R62="**",R63-2,IF(R62="*",R63-1,R63))))) | S65: =IF(S61="","",MIN(IF(S60="**",S61-2,IF(S60="*",S61-1,S61)),(IF(S62="**",S63-2,IF(S62="*",S63-1,S63))))) | T65: =IF(T61="","",MIN(IF(T60="**",T61-2,IF(T60="*",T61-1,T61)),(IF(T62="**",T63-2,IF(T62="*",T63-1,T63))))) | U65: =IF(U61="","",MIN(IF(U60="**",U61-2,IF(U60="*",U61-1,U61)),(IF(U62="**",U63-2,IF(U62="*",U63-1,U63))))) | V65: =IF(V61="","",MIN(IF(V60="**",V61-2,IF(V60="*",V61-1,V61)),(IF(V62="**",V63-2,IF(V62="*",V63-1,V63))))) | W65: =IF(W61="","",MIN(IF(W60="**",W61-2,IF(W60="*",W61-1,W61)),(IF(W62="**",W63-2,IF(W62="*",W63-1,W63))))) | X65: =IF(X61="","",MIN(IF(X60="**",X61-2,IF(X60="*",X61-1,X61)),(IF(X62="**",X63-2,IF(X62="*",X63-1,X63))))) | Y65: =IF(Y61="","",MIN(IF(Y60="**",Y61-2,IF(Y60="*",Y61-1,Y61)),(IF(Y62="**",Y63-2,IF(Y62="*",Y63-1,Y63))))) | Z65: =IF(Q65="","",SUM(Q65:Y65)) | AA65: =IF(Z65="","",Z65+O65)
D66: Points | F66: =IF(F65="","",IF(F65=F73,0.5,IF(F65<F73,1,0))) | G66: =IF(G65="","",IF(G65=G73,0.5,IF(G65<G73,1,0))) | H66: =IF(H65="","",IF(H65=H73,0.5,IF(H65<H73,1,0))) | I66: =IF(I65="","",IF(I65=I73,0.5,IF(I65<I73,1,0))) | J66: =IF(J65="","",IF(J65=J73,0.5,IF(J65<J73,1,0))) | K66: =IF(K65="","",IF(K65=K73,0.5,IF(K65<K73,1,0))) | L66: =IF(L65="","",IF(L65=L73,0.5,IF(L65<L73,1,0))) | M66: =IF(M65="","",IF(M65=M73,0.5,IF(M65<M73,1,0))) | N66: =IF(N65="","",IF(N65=N73,0.5,IF(N65<N73,1,0))) | O66: =IF(F66="","",SUM(F66:N66)) | Q66: =IF(Q65="","",IF(Q65=Q73,0.5,IF(Q65<Q73,1,0))) | R66: =IF(R65="","",IF(R65=R73,0.5,IF(R65<R73,1,0))) | S66: =IF(S65="","",IF(S65=S73,0.5,IF(S65<S73,1,0))) | T66: =IF(T65="","",IF(T65=T73,0.5,IF(T65<T73,1,0))) | U66: =IF(U65="","",IF(U65=U73,0.5,IF(U65<U73,1,0))) | V66: =IF(V65="","",IF(V65=V73,0.5,IF(V65<V73,1,0))) | W66: =IF(W65="","",IF(W65=W73,0.5,IF(W65<W73,1,0))) | X66: =IF(X65="","",IF(X65=X73,0.5,IF(X65<X73,1,0))) | Y66: =IF(Y65="","",IF(Y65=Y73,0.5,IF(Y65<Y73,1,0))) | Z66: =IF(Q66="","",SUM(Q66:Y66)) | AA66: =IF(Z66="","",Z66+O66)
E68: =IFERROR(VLOOKUP(D68,HANDICAPS!$B$8:$G$23,$B$3,FALSE),"") | F68: =IFERROR(IF($E68>18,IF(($E68-18)>F$33,"**","*"),IF($E68>=F$8,"*","")),"") -> * | G68: =IFERROR(IF($E68>18,IF(($E68-18)>G$33,"**","*"),IF($E68>=G$8,"*","")),"") -> * | H68: =IFERROR(IF($E68>18,IF(($E68-18)>H$33,"**","*"),IF($E68>=H$8,"*","")),"") -> * | I68: =IFERROR(IF($E68>18,IF(($E68-18)>I$33,"**","*"),IF($E68>=I$8,"*","")),"") -> * | J68: =IFERROR(IF($E68>18,IF(($E68-18)>J$33,"**","*"),IF($E68>=J$8,"*","")),"") -> * | K68: =IFERROR(IF($E68>18,IF(($E68-18)>K$33,"**","*"),IF($E68>=K$8,"*","")),"") -> * | L68: =IFERROR(IF($E68>18,IF(($E68-18)>L$33,"**","*"),IF($E68>=L$8,"*","")),"") -> * | M68: =IFERROR(IF($E68>18,IF(($E68-18)>M$33,"**","*"),IF($E68>=M$8,"*","")),"") -> * | N68: =IFERROR(IF($E68>18,IF(($E68-18)>N$33,"**","*"),IF($E68>=N$8,"*","")),"") -> * | O68: =IF(F69="","",SUM(F69:N69)) | Q68: =IFERROR(IF($E68>18,IF(($E68-18)>Q$33,"**","*"),IF($E68>=Q$8,"*","")),"") -> * | R68: =IFERROR(IF($E68>18,IF(($E68-18)>R$33,"**","*"),IF($E68>=R$8,"*","")),"") -> * | S68: =IFERROR(IF($E68>18,IF(($E68-18)>S$33,"**","*"),IF($E68>=S$8,"*","")),"") -> * | T68: =IFERROR(IF($E68>18,IF(($E68-18)>T$33,"**","*"),IF($E68>=T$8,"*","")),"") -> * | U68: =IFERROR(IF($E68>18,IF(($E68-18)>U$33,"**","*"),IF($E68>=U$8,"*","")),"") -> * | V68: =IFERROR(IF($E68>18,IF(($E68-18)>V$33,"**","*"),IF($E68>=V$8,"*","")),"") -> * | W68: =IFERROR(IF($E68>18,IF(($E68-18)>W$33,"**","*"),IF($E68>=W$8,"*","")),"") -> * | X68: =IFERROR(IF($E68>18,IF(($E68-18)>X$33,"**","*"),IF($E68>=X$8,"*","")),"") -> * | Y68: =IFERROR(IF($E68>18,IF(($E68-18)>Y$33,"**","*"),IF($E68>=Y$8,"*","")),"") -> * | Z68: =IF(Q69="","",SUM(Q69:Y69)) | AA68: =IF(Z68="","",SUM(O68,Z68))
E70: =IFERROR(VLOOKUP(D70,HANDICAPS!$B$8:$G$23,$B$3,FALSE),"") | F70: =IFERROR(IF($E70>18,IF(($E70-18)>F$33,"**","*"),IF($E70>=F$8,"*","")),"") -> * | G70: =IFERROR(IF($E70>18,IF(($E70-18)>G$33,"**","*"),IF($E70>=G$8,"*","")),"") -> * | H70: =IFERROR(IF($E70>18,IF(($E70-18)>H$33,"**","*"),IF($E70>=H$8,"*","")),"") -> * | I70: =IFERROR(IF($E70>18,IF(($E70-18)>I$33,"**","*"),IF($E70>=I$8,"*","")),"") -> * | J70: =IFERROR(IF($E70>18,IF(($E70-18)>J$33,"**","*"),IF($E70>=J$8,"*","")),"") -> * | K70: =IFERROR(IF($E70>18,IF(($E70-18)>K$33,"**","*"),IF($E70>=K$8,"*","")),"") -> * | L70: =IFERROR(IF($E70>18,IF(($E70-18)>L$33,"**","*"),IF($E70>=L$8,"*","")),"") -> * | M70: =IFERROR(IF($E70>18,IF(($E70-18)>M$33,"**","*"),IF($E70>=M$8,"*","")),"") -> * | N70: =IFERROR(IF($E70>18,IF(($E70-18)>N$33,"**","*"),IF($E70>=N$8,"*","")),"") -> * | O70: =IF(F71="","",SUM(F71:N71)) | Q70: =IFERROR(IF($E70>18,IF(($E70-18)>Q$33,"**","*"),IF($E70>=Q$8,"*","")),"") -> * | R70: =IFERROR(IF($E70>18,IF(($E70-18)>R$33,"**","*"),IF($E70>=R$8,"*","")),"") -> * | S70: =IFERROR(IF($E70>18,IF(($E70-18)>S$33,"**","*"),IF($E70>=S$8,"*","")),"") -> * | T70: =IFERROR(IF($E70>18,IF(($E70-18)>T$33,"**","*"),IF($E70>=T$8,"*","")),"") -> * | U70: =IFERROR(IF($E70>18,IF(($E70-18)>U$33,"**","*"),IF($E70>=U$8,"*","")),"") -> * | V70: =IFERROR(IF($E70>18,IF(($E70-18)>V$33,"**","*"),IF($E70>=V$8,"*","")),"") -> * | W70: =IFERROR(IF($E70>18,IF(($E70-18)>W$33,"**","*"),IF($E70>=W$8,"*","")),"") -> * | X70: =IFERROR(IF($E70>18,IF(($E70-18)>X$33,"**","*"),IF($E70>=X$8,"*","")),"") -> * | Y70: =IFERROR(IF($E70>18,IF(($E70-18)>Y$33,"**","*"),IF($E70>=Y$8,"*","")),"") -> * | Z70: =IF(Q71="","",SUM(Q71:Y71)) | AA70: =IF(Z70="","",SUM(O70,Z70))
...

Sheet SUMMARY
C2: DAY 1 | F2: DAY 2 | H2: DAY 3
C3: ROUND 1 | D3: ROUND 2 | E3: TOTAL | F3: ROUND 3 | G3: TOTAL | H3: ROUND 4 | I3: TOTAL
B4: TEAM EUROPE POINTS | C4: =IFERROR('ROUND 1 - FOURBALL'!AC16+'ROUND 1 - FOURBALL'!AC41+'ROUND 1 - FOURBALL'!AC66+'ROUND 1 - FOURBALL'!AC91,0) -> 37 | D4: =IFERROR('ROUND 2 - FOURBALL'!AC16+'ROUND 2 - FOURBALL'!AC41+'ROUND 2 - FOURBALL'!AC66+'ROUND 2 - FOURBALL'!AC91) -> 37.5 | E4: =C4+D4 -> 74.5 | F4: =IFERROR('ROUND 3 - FOURBALL'!AC16+'ROUND 3 - FOURBALL'!AC41+'ROUND 3 - FOURBALL'!AC66+'ROUND 3 - FOURBALL'!AC91,) -> 33 | G4: =E4+F4 -> 107.5 | H4: =IFERROR('ROUND 4 - SINGLES'!AC16+'ROUND 4 - SINGLES'!AC41+'ROUND 4 - SINGLES'!AC66+'ROUND 4 - SINGLES'!AC91+'ROUND 4 - SINGLES'!AC116+'ROUND 4 - SINGLES'!AC141+'ROUND 4 - SINGLES'!AC166+'ROUND 4 - SINGLES'!AC191,0) -> 73.5 | I4: =G4+H4 -> 181
B5: TEAM USA POINTS | C5: =IFERROR('ROUND 1 - FOURBALL'!AC24+'ROUND 1 - FOURBALL'!AC49+'ROUND 1 - FOURBALL'!AC74+'ROUND 1 - FOURBALL'!AC99,0) -> 35 | D5: =IFERROR('ROUND 2 - FOURBALL'!AC24+'ROUND 2 - FOURBALL'!AC49+'ROUND 2 - FOURBALL'!AC74+'ROUND 2 - FOURBALL'!AC99) -> 34.5 | E5: =C5+D5 -> 69.5 | F5: =IFERROR('ROUND 3 - FOURBALL'!AC24+'ROUND 3 - FOURBALL'!AC49+'ROUND 3 - FOURBALL'!AC74+'ROUND 3 - FOURBALL'!AC99,) -> 39 | G5: =E5+F5 -> 108.5 | H5: =iferror('ROUND 4 - SINGLES'!AC24+'ROUND 4 - SINGLES'!AC49+'ROUND 4 - SINGLES'!AC74+'ROUND 4 - SINGLES'!AC99+'ROUND 4 - SINGLES'!AC124+'ROUND 4 - SINGLES'!AC149+'ROUND 4 - SINGLES'!AC174+'ROUND 4 - SINGLES'!AC199,0) -> 70.5 | I5: =G5+H5 -> 179
C7: =C2 -> DAY 1 | F7: =F2 -> DAY 2 | H7: =H2 -> DAY 3
B8: BIRDIES | C8: =C3 -> ROUND 1 | D8: =D3 -> ROUND 2 | E8: =E3 -> TOTAL | F8: =F3 -> ROUND 3 | G8: =G3 -> TOTAL | H8: =H3 -> ROUND 4 | I8: =I3 -> TOTAL | J8: PRACTICE ROUND | K8: TOTAL | L8: LINE
B9: =HANDICAPS!B8 -> DEREK | C9: =VLOOKUP(B9,'ROUND 1 - FOURBALL'!$F$168:$AB$183,23,FALSE) -> 2 | D9: =VLOOKUP(B9,'ROUND 2 - FOURBALL'!$F$168:$AB$183,23,FALSE) -> 5 | E9: =C9+D9 -> 7 | F9: =VLOOKUP(B9,'ROUND 3 - FOURBALL'!$F$168:$AB$183,23,FALSE) -> 2 | G9: =E9+F9 -> 9 | H9: =VLOOKUP(B9,'ROUND 4 - SINGLES'!$F$251:$AB$266,23,FALSE) -> 0 | I9: =G9+H9 -> 9 | J9: 3 | K9: =I9+J9 -> 12 | L9: 8.5
B10: =HANDICAPS!B9 -> SCOTT | C10: =VLOOKUP(B10,'ROUND 1 - FOURBALL'!$F$168:$AB$183,23,FALSE) -> 3 | D10: =VLOOKUP(B10,'ROUND 2 - FOURBALL'!$F$168:$AB$183,23,FALSE) -> 3 | E10: =C10+D10 -> 6 | F10: =VLOOKUP(B10,'ROUND 3 - FOURBALL'!$F$168:$AB$183,23,FALSE) -> 1 | G10: =E10+F10 -> 7 | H10: =VLOOKUP(B10,'ROUND 4 - SINGLES'!$F$251:$AB$266,23,FALSE) -> 0 | I10: =G10+H10 -> 7 | J10: 2 | K10: =I10+J10 -> 9 | L10: 7.5
B11: =HANDICAPS!B10 -> WAYS | C11: =VLOOKUP(B11,'ROUND 1 - FOURBALL'!$F$168:$AB$183,23,FALSE) -> 2 | D11: =VLOOKUP(B11,'ROUND 2 - FOURBALL'!$F$168:$AB$183,23,FALSE) -> 2 | E11: =C11+D11 -> 4 | F11: =VLOOKUP(B11,'ROUND 3 - FOURBALL'!$F$168:$AB$183,23,FALSE) -> 1 | G11: =E11+F11 -> 5 | H11: =VLOOKUP(B11,'ROUND 4 - SINGLES'!$F$251:$AB$266,23,FALSE) -> 1 | I11: =G11+H11 -> 6 | J11: 1 | K11: =I11+J11 -> 7 | L11: 6.5
B12: =HANDICAPS!B11 -> BEN | C12: =VLOOKUP(B12,'ROUND 1 - FOURBALL'!$F$168:$AB$183,23,FALSE) -> 3 | D12: =VLOOKUP(B12,'ROUND 2 - FOURBALL'!$F$168:$AB$183,23,FALSE) -> 1 | E12: =C12+D12 -> 4 | F12: =VLOOKUP(B12,'ROUND 3 - FOURBALL'!$F$168:$AB$183,23,FALSE) -> 2 | G12: =E12+F12 -> 6 | H12: =VLOOKUP(B12,'ROUND 4 - SINGLES'!$F$251:$AB$266,23,FALSE) -> 3 | I12: =G12+H12 -> 9 | J12: 0 | K12: =I12+J12 -> 9 | L12: 6.5
B13: =HANDICAPS!B12 -> DANNY | C13: =VLOOKUP(B13,'ROUND 1 - FOURBALL'!$F$168:$AB$183,23,FALSE) -> 2 | D13: =VLOOKUP(B13,'ROUND 2 - FOURBALL'!$F$168:$AB$183,23,FALSE) -> 0 | E13: =C13+D13 -> 2 | F13: =VLOOKUP(B13,'ROUND 3 - FOURBALL'!$F$168:$AB$183,23,FALSE) -> 2 | G13: =E13+F13 -> 4 | H13: =VLOOKUP(B13,'ROUND 4 - SINGLES'!$F$251:$AB$266,23,FALSE) -> 0 | I13: =G13+H13 -> 4 | J13: 1 | K13: =I13+J13 -> 5 | L13: 5.5
B14: =HANDICAPS!B13 -> ZACH | C14: =VLOOKUP(B14,'ROUND 1 - FOURBALL'!$F$168:$AB$183,23,FALSE) -> 0 | D14: =VLOOKUP(B14,'ROUND 2 - FOURBALL'!$F$168:$AB$183,23,FALSE) -> 2 | E14: =C14+D14 -> 2 | F14: =VLOOKUP(B14,'ROUND 3 - FOURBALL'!$F$168:$AB$183,23,FALSE) -> 1 | G14: =E14+F14 -> 3 | H14: =VLOOKUP(B14,'ROUND 4 - SINGLES'!$F$251:$AB$266,23,FALSE) -> 0 | I14: =G14+H14 -> 3 | J14: 1 | K14: =I14+J14 -> 4 | L14: 5.5
B15: =HANDICAPS!B14 -> SLICK | C15: =VLOOKUP(B15,'ROUND 1 - FOURBALL'!$F$168:$AB$183,23,FALSE) -> 0 | D15: =VLOOKUP(B15,'ROUND 2 - FOURBALL'!$F$168:$AB$183,23,FALSE) -> 1 | E15: =C15+D15 -> 1 | F15: =VLOOKUP(B15,'ROUND 3 - FOURBALL'!$F$168:$AB$183,23,FALSE) -> 0 | G15: =E15+F15 -> 1 | H15: =VLOOKUP(B15,'ROUND 4 - SINGLES'!$F$251:$AB$266,23,FALSE) -> 1 | I15: =G15+H15 -> 2 | J15: 0 | K15: =I15+J15 -> 2 | L15: 4.5
B16: =HANDICAPS!B15 -> PAXTON | C16: =VLOOKUP(B16,'ROUND 1 - FOURBALL'!$F$168:$AB$183,23,FALSE) -> 2 | D16: =VLOOKUP(B16,'ROUND 2 - FOURBALL'!$F$168:$AB$183,23,FALSE) -> 0 | E16: =C16+D16 -> 2 | F16: =VLOOKUP(B16,'ROUND 3 - FOURBALL'!$F$168:$AB$183,23,FALSE) -> 1 | G16: =E16+F16 -> 3 | H16: =VLOOKUP(B16,'ROUND 4 - SINGLES'!$F$251:$AB$266,23,FALSE) -> 0 | I16: =G16+H16 -> 3 | J16: 0 | K16: =I16+J16 -> 3 | L16: 3.5
B17: =HANDICAPS!B16 -> DYLAN | C17: =VLOOKUP(B17,'ROUND 1 - FOURBALL'!$F$168:$AB$183,23,FALSE) -> 0 | D17: =VLOOKUP(B17,'ROUND 2 - FOURBALL'!$F$168:$AB$183,23,FALSE) -> 0 | E17: =C17+D17 -> 0 | F17: =VLOOKUP(B17,'ROUND 3 - FOURBALL'!$F$168:$AB$183,23,FALSE) -> 0 | G17: =E17+F17 -> 0 | H17: =VLOOKUP(B17,'ROUND 4 - SINGLES'!$F$251:$AB$266,23,FALSE) -> 0 | I17: =G17+H17 -> 0 | J17: 0 | K17: =I17+J17 -> 0 | L17: 3
B18: =HANDICAPS!B17 -> TOM | C18: =VLOOKUP(B18,'ROUND 1 - FOURBALL'!$F$168:$AB$183,23,FALSE) -> 0 | D18: =VLOOKUP(B18,'ROUND 2 - FOURBALL'!$F$168:$AB$183,23,FALSE) -> 1 | E18: =C18+D18 -> 1 | F18: =VLOOKUP(B18,'ROUND 3 - FOURBALL'!$F$168:$AB$183,23,FALSE) -> 0 | G18: =E18+F18 -> 1 | H18: =VLOOKUP(B18,'ROUND 4 - SINGLES'!$F$251:$AB$266,23,FALSE) -> 0 | I18: =G18+H18 -> 1 | J18: 0 | K18: =I18+J18 -> 1 | L18: 2.5
B19: =HANDICAPS!B18 -> ERIC | C19: =VLOOKUP(B19,'ROUND 1 - FOURBALL'!$F$168:$AB$183,23,FALSE) -> 1 | D19: =VLOOKUP(B19,'ROUND 2 - FOURBALL'!$F$168:$AB$183,23,FALSE) -> 1 | E19: =C19+D19 -> 2 | F19: =VLOOKUP(B19,'ROUND 3 - FOURBALL'!$F$168:$AB$183,23,FALSE) -> 0 | G19: =E19+F19 -> 2 | H19: =VLOOKUP(B19,'ROUND 4 - SINGLES'!$F$251:$AB$266,23,FALSE) -> 1 | I19: =G19+H19 -> 3 | J19: 0 | K19: =I19+J19 -> 3 | L19: 2.5
B20: =HANDICAPS!B19 -> MAX | C20: =VLOOKUP(B20,'ROUND 1 - FOURBALL'!$F$168:$AB$183,23,FALSE) -> 0 | D20: =VLOOKUP(B20,'ROUND 2 - FOURBALL'!$F$168:$AB$183,23,FALSE) -> 0 | E20: =C20+D20 -> 0 | F20: =VLOOKUP(B20,'ROUND 3 - FOURBALL'!$F$168:$AB$183,23,FALSE) -> 0 | G20: =E20+F20 -> 0 | H20: =VLOOKUP(B20,'ROUND 4 - SINGLES'!$F$251:$AB$266,23,FALSE) -> 1 | I20: =G20+H20 -> 1 | J20: 0 | K20: =I20+J20 -> 1 | L20: 2.5
... B23: =HANDICAPS!B22 -> SKYLAR | C23: =VLOOKUP(B23,'ROUND 1 - FOURBALL'!$F$168:$AB$183,23,FALSE) -> 0 | D23: =VLOOKUP(B23,'ROUND 2 - FOURBALL'!$F$168:$AB$183,23,FALSE) -> 0 | E23: =C23+D23 -> 0 | F23: =VLOOKUP(B23,'ROUND 3 - FOURBALL'!$F$168:$AB$183,23,FALSE) -> 0 | G23: =E23+F23 -> 0 | H23: =VLOOKUP(B23,'ROUND 4 - SINGLES'!$F$251:$AB$266,23,FALSE) -> 0 | I23: =G23+H23 -> 0 | J23: 0 | K23: =I23+J23 -> 0 | L23: 0.5
B24: =HANDICAPS!B23 -> RYAN | C24: =VLOOKUP(B24,'ROUND 1 - FOURBALL'!$F$168:$AB$183,23,FALSE) -> 0 | D24: =VLOOKUP(B24,'ROUND 2 - FOURBALL'!$F$168:$AB$183,23,FALSE) -> 0 | E24: =C24+D24 -> 0 | F24: =VLOOKUP(B24,'ROUND 3 - FOURBALL'!$F$168:$AB$183,23,FALSE) -> 0 | G24: =E24+F24 -> 0 | H24: =VLOOKUP(B24,'ROUND 4 - SINGLES'!$F$251:$AB$266,23,FALSE) -> 0 | I24: =G24+H24 -> 0 | J24: 0 | K24: 0 | L24: 0.5
B25: TOTALS | C25: =SUM(C9:C24) -> 15 | D25: =SUM(D9:D24) -> 16 | E25: =SUM(E9:E24) -> 31 | F25: =SUM(F9:F24) -> 10 | G25: =SUM(G9:G24) -> 41 | H25: =SUM(H9:H24) -> 7 | I25: =SUM(I9:I24) -> 48
B27: BUY IN | C27: 20 | I27: BUY IN | J27: 25
B28: SKINS | C28: ROUND 1 | D28: ROUND 2 | E28: ROUND 3 | F28: ROUND 4 | G28: =G8 -> TOTAL | I28: TILT | J28: OPT IN? | L28: ROUND 1 | M28: ROUND 2 | N28: ROUND 3 | O28: ROUND 4 | P28: TOTAL
B29: =B9 -> DEREK | C29: ='ROUND 1 - FOURBALL'!AF144 -> 0 | D29: ='ROUND 2 - FOURBALL'!AF144 -> 0 | E29: ='ROUND 3 - FOURBALL'!AF144 -> 0 | F29: ='ROUND 4 - SINGLES'!AF227 -> 0 | G29: =SUM(C29:F29) -> 0 | I29: =B29 -> DEREK | J29: Y | L29: =if($J29="N","DNQ",vlookup($I29,'TILT Round 1'!$C:$Z,24,false)) -> 16 | M29: =if($J29="N","DNQ",vlookup($I29,'TILT Round 2'!$C:$Z,24,false)) -> 46 | N29: =if($J29="N","DNQ",vlookup($I29,'TILT Round 3'!$C:$Z,24,false)) -> 26 | O29: =iferror(if($J29="N","DNQ",vlookup($I29,'TILT Round 4'!$C:$Z,24,false)),0) -> 10 | P29: =if(J29="N","DNQ",SUM(L29:O29)) -> 98
B30: =B10 -> SCOTT | C30: ='ROUND 1 - FOURBALL'!AF145 -> 70 | D30: ='ROUND 2 - FOURBALL'!AF145 -> 0 | E30: ='ROUND 3 - FOURBALL'!AF145 -> 0 | F30: ='ROUND 4 - SINGLES'!AF228 -> 0 | G30: =SUM(C30:F30) -> 70 | I30: =B30 -> SCOTT | J30: Y | L30: =if(J30="N","DNQ",vlookup($I30,'TILT Round 1'!$C:$Z,24,false)) -> 24 | M30: =if($J30="N","DNQ",vlookup($I30,'TILT Round 2'!$C:$Z,24,false)) -> 28 | N30: =if($J30="N","DNQ",vlookup($I30,'TILT Round 3'!$C:$Z,24,false)) -> 30 | O30: =iferror(if($J30="N","DNQ",vlookup($I30,'TILT Round 4'!$C:$Z,24,false)),0) -> 16 | P30: =if(J30="N","DNQ",SUM(L30:O30)) -> 98
B31: =B11 -> WAYS | C31: ='ROUND 1 - FOURBALL'!AF146 -> 0 | D31: ='ROUND 2 - FOURBALL'!AF146 -> 46.666667 | E31: ='ROUND 3 - FOURBALL'!AF146 -> 0 | F31: ='ROUND 4 - SINGLES'!AF229 -> 31.111111 | G31: =SUM(C31:F31) -> 77.777778 | I31: =B31 -> WAYS | J31: Y | L31: =if(J31="N","DNQ",vlookup($I31,'TILT Round 1'!$C:$Z,24,false)) -> 24 | M31: =if($J31="N","DNQ",vlookup($I31,'TILT Round 2'!$C:$Z,24,false)) -> 34 | N31: =if($J31="N","DNQ",vlookup($I31,'TILT Round 3'!$C:$Z,24,false)) -> 20 | O31: =iferror(if($J31="N","DNQ",vlookup($I31,'TILT Round 4'!$C:$Z,24,false)),0) -> 38 | P31: =if(J31="N","DNQ",SUM(L31:O31)) -> 116
B32: =B12 -> BEN | C32: ='ROUND 1 - FOURBALL'!AF147 -> 70 | D32: ='ROUND 2 - FOURBALL'!AF147 -> 0 | E32: ='ROUND 3 - FOURBALL'!AF147 -> 56 | F32: ='ROUND 4 - SINGLES'!AF230 -> 31.111111 | G32: =SUM(C32:F32) -> 157.11111 | I32: =B32 -> BEN | J32: Y | L32: =if(J32="N","DNQ",vlookup($I32,'TILT Round 1'!$C:$Z,24,false)) -> 40 | M32: =if($J32="N","DNQ",vlookup($I32,'TILT Round 2'!$C:$Z,24,false)) -> 52 | N32: =if($J32="N","DNQ",vlookup($I32,'TILT Round 3'!$C:$Z,24,false)) -> 42 | O32: =iferror(if($J32="N","DNQ",vlookup($I32,'TILT Round 4'!$C:$Z,24,false)),0) -> 40 | P32: =if(J32="N","DNQ",SUM(L32:O32)) -> 174
B33: =B13 -> DANNY | C33: ='ROUND 1 - FOURBALL'!AF148 -> 70 | D33: ='ROUND 2 - FOURBALL'!AF148 -> 0 | E33: ='ROUND 3 - FOURBALL'!AF148 -> 0 | F33: ='ROUND 4 - SINGLES'!AF231 -> 0 | G33: =SUM(C33:F33) -> 70 | I33: =B33 -> DANNY | J33: Y | L33: =if(J33="N","DNQ",vlookup($I33,'TILT Round 1'!$C:$Z,24,false)) -> 10 | M33: =if($J33="N","DNQ",vlookup($I33,'TILT Round 2'!$C:$Z,24,false)) -> 36 | N33: =if($J33="N","DNQ",vlookup($I33,'TILT Round 3'!$C:$Z,24,false)) -> 42 | O33: =iferror(if($J33="N","DNQ",vlookup($I33,'TILT Round 4'!$C:$Z,24,false)),0) -> 8 | P33: =if(J33="N","DNQ",SUM(L33:O33)) -> 96
B34: =B14 -> ZACH | C34: ='ROUND 1 - FOURBALL'!AF149 -> 0 | D34: ='ROUND 2 - FOURBALL'!AF149 -> 93.333333 | E34: ='ROUND 3 - FOURBALL'!AF149 -> 56 | F34: ='ROUND 4 - SINGLES'!AF232 -> 0 | G34: =SUM(C34:F34) -> 149.33333 | I34: =B34 -> ZACH | J34: Y | L34: =if(J34="N","DNQ",vlookup($I34,'TILT Round 1'!$C:$Z,24,false)) -> 24 | M34: =if($J34="N","DNQ",vlookup($I34,'TILT Round 2'!$C:$Z,24,false)) -> 42 | N34: =if($J34="N","DNQ",vlookup($I34,'TILT Round 3'!$C:$Z,24,false)) -> 26 | O34: =iferror(if($J34="N","DNQ",vlookup($I34,'TILT Round 4'!$C:$Z,24,false)),0) -> 8 | P34: =if(J34="N","DNQ",SUM(L34:O34)) -> 100
B35: =B15 -> SLICK | C35: ='ROUND 1 - FOURBALL'!AF150 -> 0 | D35: ='ROUND 2 - FOURBALL'!AF150 -> 46.666667 | E35: ='ROUND 3 - FOURBALL'!AF150 -> 0 | F35: ='ROUND 4 - SINGLES'!AF233 -> 31.111111 | G35: =SUM(C35:F35) -> 77.777778 | I35: =B35 -> SLICK | J35: Y | L35: =if(J35="N","DNQ",vlookup($I35,'TILT Round 1'!$C:$Z,24,false)) -> 60 | M35: =if($J35="N","DNQ",vlookup($I35,'TILT Round 2'!$C:$Z,24,false)) -> 48 | N35: =if($J35="N","DNQ",vlookup($I35,'TILT Round 3'!$C:$Z,24,false)) -> 30 | O35: =iferror(if($J35="N","DNQ",vlookup($I35,'TILT Round 4'!$C:$Z,24,false)),0) -> 8 | P35: =if(J35="N","DNQ",SUM(L35:O35)) -> 146
B36: =B16 -> PAXTON | C36: ='ROUND 1 - FOURBALL'!AF151 -> 0 | D36: ='ROUND 2 - FOURBALL'!AF151 -> 0 | E36: ='ROUND 3 - FOURBALL'!AF151 -> 56 | F36: ='ROUND 4 - SINGLES'!AF234 -> 31.111111 | G36: =SUM(C36:F36) -> 87.111111 | I36: =B36 -> PAXTON | J36: Y | L36: =if(J36="N","DNQ",vlookup($I36,'TILT Round 1'!$C:$Z,24,false)) -> 70 | M36: =if($J36="N","DNQ",vlookup($I36,'TILT Round 2'!$C:$Z,24,false)) -> 0 | N36: =if($J36="N","DNQ",vlookup($I36,'TILT Round 3'!$C:$Z,24,false)) -> 22 | O36: =iferror(if($J36="N","DNQ",vlookup($I36,'TILT Round 4'!$C:$Z,24,false)),0) -> 22 | P36: =if(J36="N","DNQ",SUM(L36:O36)) -> 114
B37: =B17 -> DYLAN | C37: ='ROUND 1 - FOURBALL'!AF152 -> 0 | D37: ='ROUND 2 - FOURBALL'!AF152 -> 0 | E37: ='ROUND 3 - FOURBALL'!AF152 -> 0 | F37: ='ROUND 4 - SINGLES'!AF235 -> 0 | G37: =SUM(C37:F37) -> 0 | I37: =B37 -> DYLAN | J37: Y | L37: =if(J37="N","DNQ",vlookup($I37,'TILT Round 1'!$C:$Z,24,false)) -> 58 | M37: =if($J37="N","DNQ",vlookup($I37,'TILT Round 2'!$C:$Z,24,false)) -> 32 | N37: =if($J37="N","DNQ",vlookup($I37,'TILT Round 3'!$C:$Z,24,false)) -> 14 | O37: =iferror(if($J37="N","DNQ",vlookup($I37,'TILT Round 4'!$C:$Z,24,false)),0) -> 26 | P37: =if(J37="N","DNQ",SUM(L37:O37)) -> 130
B38: =B18 -> TOM | C38: ='ROUND 1 - FOURBALL'!AF153 -> 0 | D38: ='ROUND 2 - FOURBALL'!AF153 -> 0 | E38: ='ROUND 3 - FOURBALL'!AF153 -> 56 | F38: ='ROUND 4 - SINGLES'!AF236 -> 0 | G38: =SUM(C38:F38) -> 56 | I38: =B38 -> TOM | J38: Y | L38: =if(J38="N","DNQ",vlookup($I38,'TILT Round 1'!$C:$Z,24,false)) -> 24 | M38: =if($J38="N","DNQ",vlookup($I38,'TILT Round 2'!$C:$Z,24,false)) -> 18 | N38: =if($J38="N","DNQ",vlookup($I38,'TILT Round 3'!$C:$Z,24,false)) -> 16 | O38: =iferror(if($J38="N","DNQ",vlookup($I38,'TILT Round 4'!$C:$Z,24,false)),0) -> 18 | P38: =if(J38="N","DNQ",SUM(L38:O38)) -> 76
B39: =B19 -> ERIC | C39: ='ROUND 1 - FOURBALL'!AF154 -> 0 | D39: ='ROUND 2 - FOURBALL'!AF154 -> 0 | E39: ='ROUND 3 - FOURBALL'!AF154 -> 0 | F39: ='ROUND 4 - SINGLES'!AF237 -> 0 | G39: =SUM(C39:F39) -> 0 | I39: =B39 -> ERIC | J39: N | L39: =if(J39="N","DNQ",vlookup($I39,'TILT Round 1'!$C:$Z,24,false)) -> DNQ | M39: =if($J39="N","DNQ",vlookup($I39,'TILT Round 2'!$C:$Z,24,false)) -> DNQ | N39: =if($J39="N","DNQ",vlookup($I39,'TILT Round 3'!$C:$Z,24,false)) -> DNQ | O39: =iferror(if($J39="N","DNQ",vlookup($I39,'TILT Round 4'!$C:$Z,24,false)),0) -> DNQ | P39: =if(J39="N","DNQ",SUM(L39:O39)) -> DNQ
B40: =B20 -> MAX | C40: ='ROUND 1 - FOURBALL'!AF155 -> 0 | D40: ='ROUND 2 - FOURBALL'!AF155 -> 0 | E40: ='ROUND 3 - FOURBALL'!AF155 -> 0 | F40: ='ROUND 4 - SINGLES'!AF238 -> 62.222222 | G40: =SUM(C40:F40) -> 62.222222 | I40: =B40 -> MAX | J40: N | L40: =if(J40="N","DNQ",vlookup($I40,'TILT Round 1'!$C:$Z,24,false)) -> DNQ | M40: =if($J40="N","DNQ",vlookup($I40,'TILT Round 2'!$C:$Z,24,false)) -> DNQ | N40: =if($J40="N","DNQ",vlookup($I40,'TILT Round 3'!$C:$Z,24,false)) -> DNQ | O40: =iferror(if($J40="N","DNQ",vlookup($I40,'TILT Round 4'!$C:$Z,24,false)),0) -> DNQ | P40: =if(J40="N","DNQ",SUM(L40:O40)) -> DNQ
B41: =B21 -> KIP | C41: ='ROUND 1 - FOURBALL'!AF156 -> 0 | D41: ='ROUND 2 - FOURBALL'!AF156 -> 0 | E41: ='ROUND 3 - FOURBALL'!AF156 -> 0 | F41: ='ROUND 4 - SINGLES'!AF239 -> 31.111111 | G41: =SUM(C41:F41) -> 31.111111 | I41: =B41 -> KIP | J41: Y | L41: =if(J41="N","DNQ",vlookup($I41,'TILT Round 1'!$C:$Z,24,false)) -> -12 | M41: =if($J41="N","DNQ",vlookup($I41,'TILT Round 2'!$C:$Z,24,false)) -> 4 | N41: =if($J41="N","DNQ",vlookup($I41,'TILT Round 3'!$C:$Z,24,false)) -> -30 | O41: =iferror(if($J41="N","DNQ",vlookup($I41,'TILT Round 4'!$C:$Z,24,false)),0) -> 8 | P41: =if(J41="N","DNQ",SUM(L41:O41)) -> -30
... B44: =B24 -> RYAN | C44: ='ROUND 1 - FOURBALL'!AF159 -> 70 | D44: ='ROUND 2 - FOURBALL'!AF159 -> 46.666667 | E44: ='ROUND 3 - FOURBALL'!AF159 -> 56 | F44: ='ROUND 4 - SINGLES'!AF242 -> 62.222222 | G44: =SUM(C44:F44) -> 234.88889 | I44: =B44 -> RYAN | J44: N | L44: =if(J44="N","DNQ",vlookup($I44,'TILT Round 1'!$C:$Z,24,false)) -> DNQ | M44: =if($J44="N","DNQ",vlookup($I44,'TILT Round 2'!$C:$Z,24,false)) -> DNQ | N44: =if($J44="N","DNQ",vlookup($I44,'TILT Round 3'!$C:$Z,24,false)) -> DNQ | O44: =iferror(if($J44="N","DNQ",vlookup($I44,'TILT Round 4'!$C:$Z,24,false)),0) -> DNQ | P44: =if(J44="N","DNQ",SUM(L44:O44)) -> DNQ
B45: =B25 -> TOTALS | C45: =SUM(C29:C44) -> 280 | D45: =SUM(D29:D44) -> 280 | E45: =SUM(E29:E44) -> 280 | F45: =SUM(F29:F44) -> 280 | G45: =SUM(G29:G44) -> 1120

Sheet Ledger
A2: Bettor | B2: Wager | D2: RESULT
A3: Danny | B3: OVER 5.5 birdies | C3: 20 | D3: LOSS | G3: Danny | H3: -25 | I3: paid | J3: -25
A4: Ways | B4: OVER 6.5 | C4: 20 | D4: WIN | G4: Ways | H4: 10 | I4: paid | J4: 90
A5: Dylan | B5: Europe to win | C5: 20 | D5: WIN | G5: Dylan | H5: -5 | I5: splitwise
A6: WAYS | B6: BEN OVER | C6: 5 | D6: WIN | G6: Zach | H6: -17 | I6: splitwise
A7: WAYS | B7: ZACH OVER | C7: 5 | D7: LOSS | G7: Paxton | H7: 5 | I7: splitwise
A8: WAYS | B8: TOM OVER | C8: 5 | D8: LOSS | G8: Stitt | H8: -5 | I8: venmo
A9: WAYS | B9: DMO OVER | C9: 5 | D9: LOSS | G9: Kip | H9: 10 | I9: splitwise
A10: WAYS | B10: SHEPP OVER | C10: 5 | D10: LOSS | G10: Tom | H10: -45 | I10: splitwise
A11: WAYS | B11: SKY OVER | C11: 5 | D11: LOSS | G11: Max | H11: 20 | I11: paid | J11: 30
A12: WAYS | B12: DEREK U | C12: 5 | D12: LOSS
A13: WAYS | B13: SCOTT U | C13: 5 | D13: LOSS
A14: WAYS | B14: DYLAN U | C14: 5 | D14: WIN
A15: WAYS | B15: ERIC U | C15: 5 | D15: LOSS
A16: WAYS | B16: ALEX U | C16: 5 | D16: WIN
A17: WAYS | B17: MAX U | C17: 5 | D17: WIN
A18: WAYS | B18: RYAN U | C18: 5 | D18: WIN
A19: WAYS | B19: KIP U | C19: 5 | D19: WIN
A20: DYLAN | B20: OVER 3 BIRDIES | C20: 20 | D20: LOSS
A21: ZACH | B21: HOLE IN ONE | C21: 2 | D21: LOSS
A22: DANNY | B22: HOLE IN ONE | C22: 5 | D22: LOSS
A23: PAXTON | B23: OVER 3.5 | C23: 20 | D23: LOSS
... A45: MAX | B45: TOTAL OVER 74 | C45: 5 | D45: LOSS

Sheet HANDICAPS
C2: TEES | D2: ORANGE | E2: ORANGE | F2: ORANGE | G2: COMBO | I2: RULES
C3: YARDAGE | D3: 6228 | E3: 6228 | F3: 6352 | G3: 6501 | I3: HAVE FUN OUT THERE GENTLEMEN
C4: SLOPE | D4: 143 | E4: 143 | F4: 132 | G4: 133 | I4: BREAKFAST BALL - AM ROUNDS ONLY
C5: RATING | D5: 71 | E5: 71 | F5: 70.3 | G5: 71 | I5: WINTER RULES IN YOUR FAIRWAY (ROLL THE BALL)
B6: 0.9 | C6: PAR | D6: 72 | E6: 72 | F6: 73 | G6: 72 | I6: GENTLEMAN'S DROP (LEAF RULE/NORMAL ROUGH)
B7: PLAYER | C7: INDEX | D7: BAY HARBOR | E7: BAY HARBOR | F7: ARTHUR HILLS | G7: MONUMENT | I7: RAKE AND PLACE IN THE TRAPS (SAME SPOT)
B8: DEREK | C8: 0.4 | D8: =ROUND(ROUND($C8*(D$4/113)+(D$5-D$6),0)*$B$6,0) -> 0 | E8: =ROUND(ROUND($C8*(E$4/113)+(E$5-E$6),0)*$B$6,0) -> 0 | F8: =ROUND(ROUND($C8*(F$4/113)+(F$5-F$6),0)*$B$6,0) -> -2 | G8: =ROUND(ROUND($C8*(G$4/113)+(G$5-G$6),0)*$B$6,0) -> -1 | I8: STROKE AND DISTANCE FROM TEES - EVERYTHING LAT.
B9: SCOTT | C9: 1.5 | D9: =ROUND(ROUND($C9*(D$4/113)+(D$5-D$6),0)*$B$6,0) -> 1 | E9: =ROUND(ROUND($C9*(E$4/113)+(E$5-E$6),0)*$B$6,0) -> 1 | F9: =ROUND(ROUND($C9*(F$4/113)+(F$5-F$6),0)*$B$6,0) -> -1 | G9: =ROUND(ROUND($C9*(G$4/113)+(G$5-G$6),0)*$B$6,0) -> 1 | I9: MAX DOUBLE PAR - PLEASE PICK UP TO KEEP PACE
B10: WAYS | C10: 6.8 | D10: =ROUND(ROUND($C10*(D$4/113)+(D$5-D$6),0)*$B$6,0) -> 7 | E10: =ROUND(ROUND($C10*(E$4/113)+(E$5-E$6),0)*$B$6,0) -> 7 | F10: =ROUND(ROUND($C10*(F$4/113)+(F$5-F$6),0)*$B$6,0) -> 5 | G10: =ROUND(ROUND($C10*(G$4/113)+(G$5-G$6),0)*$B$6,0) -> 6 | I10: CASH/CARD ONLY ON THE GOLF COURSE FOR BOOZE
B11: BEN | C11: 6.8 | D11: =ROUND(ROUND($C11*(D$4/113)+(D$5-D$6),0)*$B$6,0) -> 7 | E11: =ROUND(ROUND($C11*(E$4/113)+(E$5-E$6),0)*$B$6,0) -> 7 | F11: =ROUND(ROUND($C11*(F$4/113)+(F$5-F$6),0)*$B$6,0) -> 5 | G11: =ROUND(ROUND($C11*(G$4/113)+(G$5-G$6),0)*$B$6,0) -> 6 | I11: DON’T BE A CUNT LIKE THE GUY WALKING HIS DOG
B12: DANNY | C12: 7.1 | D12: =ROUND(ROUND($C12*(D$4/113)+(D$5-D$6),0)*$B$6,0) -> 7 | E12: =ROUND(ROUND($C12*(E$4/113)+(E$5-E$6),0)*$B$6,0) -> 7 | F12: =ROUND(ROUND($C12*(F$4/113)+(F$5-F$6),0)*$B$6,0) -> 5 | G12: =ROUND(ROUND($C12*(G$4/113)+(G$5-G$6),0)*$B$6,0) -> 6
B13: ZACH | C13: 7.3 | D13: =ROUND(ROUND($C13*(D$4/113)+(D$5-D$6),0)*$B$6,0) -> 7 | E13: =ROUND(ROUND($C13*(E$4/113)+(E$5-E$6),0)*$B$6,0) -> 7 | F13: =ROUND(ROUND($C13*(F$4/113)+(F$5-F$6),0)*$B$6,0) -> 5 | G13: =ROUND(ROUND($C13*(G$4/113)+(G$5-G$6),0)*$B$6,0) -> 7
